#VRML_SIM R2023b utf8

EXTERNPROTO "https://raw.githubusercontent.com/cyberbotics/webots/R2023b/projects/objects/backgrounds/protos/TexturedBackground.proto"
EXTERNPROTO "https://raw.githubusercontent.com/cyberbotics/webots/R2023b/projects/objects/backgrounds/protos/TexturedBackgroundLight.proto"
EXTERNPROTO "https://raw.githubusercontent.com/cyberbotics/webots/R2023b/projects/objects/floors/protos/RectangleArena.proto"

WorldInfo {
}
Viewpoint {
  orientation 0.5805817211765294 0.08307361408419746 -0.8099528626276274 2.77874994504413
  position 10.865713669118254 1.2460501132344546 13.353869341030387
}
TexturedBackground {
}
TexturedBackgroundLight {
}
RectangleArena {
  translation -0.7 -2.08 3.28841e-06
  rotation 0 -1 0 -5.307179586466759e-06
  floorSize 20 20
  floorTileSize 1 1
  wallHeight 0.6
}
DEF maze Solid {
  translation -7.89 -0.09 0.2
  children [
    DEF wall Solid {
      translation -1.7300616701274345 7.267589871483773 -0.018367776187945883
      rotation -0.01819667011842785 0.9785492916554994 -0.2052076143741296 1.0477690224518934e-05
      children [
        DEF wall Shape {
          appearance PBRAppearance {
            baseColor 0 0 0
          }
          geometry Box {
            size 0.1 1.5 0.4
          }
        }
      ]
      boundingObject USE wall
      physics Physics {
      }
      linearVelocity 4.450450271621232e-08 2.062411800564776e-06 -7.10730814462193e-06
      angularVelocity -1.680657477595756e-10 8.529476887375042e-13 3.3439262197387406e-08
    }
    DEF wall Solid {
      translation -0.0929516954534666 7.2748404652080945 -0.018341228423513545
      rotation 0.00021799607675316692 0.0001904556482104722 -0.9999999581021776 0.002262059264982139
      children [
        DEF wall Shape {
          appearance PBRAppearance {
            baseColor 0 0 0
          }
          geometry Box {
            size 0.1 1.5 0.4
          }
        }
      ]
      name "solid(1)"
      boundingObject USE wall
      physics Physics {
      }
      linearVelocity 2.5820877231392622e-05 -4.961129419617111e-07 -7.107475735150768e-06
      angularVelocity 3.088072042324934e-11 1.5990215112114439e-09 1.9361627119458417e-05
    }
    DEF wall Solid {
      translation -0.1180801264968876 5.776431454235931 -0.018341264625107906
      rotation -1.8769449520742088e-05 -1.7857214180486225e-05 -0.9999999996644139 0.0235617373766752
      children [
        DEF wall Shape {
          appearance PBRAppearance {
            baseColor 0 0 0
          }
          geometry Box {
            size 0.1 1.5 0.4
          }
        }
      ]
      name "solid(2)"
      boundingObject USE wall
      physics Physics {
      }
      linearVelocity -3.170394186513925e-05 -9.323591039058468e-06 -7.107607814274655e-06
      angularVelocity 1.3031965979300054e-10 -1.5918597305984926e-09 1.5079078161509365e-05
    }
    DEF wall Solid {
      translation -1.7300115440701207 5.774413105337357 -0.018341880898754104
      rotation -0.4266938793501437 -0.0409556232293325 0.9034683006342956 5.575740877783091e-06
      children [
        DEF wall Shape {
          appearance PBRAppearance {
            baseColor 0 0 0
          }
          geometry Box {
            size 0.1 1.5 0.4
          }
        }
      ]
      name "solid(3)"
      boundingObject USE wall
      physics Physics {
      }
      linearVelocity 1.8531498779763162e-07 -8.732082985868032e-07 -7.107491964900333e-06
      angularVelocity -1.792193089058506e-10 3.29413971830289e-12 2.0453833069104353e-07
    }
    DEF wall Solid {
      translation -1.730003273406921 4.278352708809187 -0.018338075662884784
      rotation 0.030955175990933163 -0.0025524670623183927 0.9995175145995522 1.0595208554211621e-05
      children [
        DEF wall Shape {
          appearance PBRAppearance {
            baseColor 0 0 0
          }
          geometry Box {
            size 0.1 1.5 0.4
          }
        }
      ]
      name "solid(4)"
      boundingObject USE wall
      physics Physics {
      }
      linearVelocity 2.3252887456108862e-07 -8.705414860628129e-07 -7.10719851443552e-06
      angularVelocity -4.2146840397022556e-10 -2.6548478446560877e-11 5.335261246285e-07
    }
    DEF wall Solid {
      translation -0.9399963375117553 3.479631192963324 -0.018338315692357388
      rotation -1.7277243936850003e-09 8.673362052450355e-09 -1 1.5705195274187187
      children [
        DEF wall Shape {
          appearance PBRAppearance {
            baseColor 0 0 0
          }
          geometry Box {
            size 0.1 1.5 0.4
          }
        }
      ]
      name "solid(5)"
      boundingObject USE wall
      physics Physics {
      }
      linearVelocity -4.5562243187995434e-07 -5.080183393696348e-07 -7.1077748388540484e-06
      angularVelocity -2.8618491744612648e-11 -3.3822950186286665e-10 1.2330149096154206e-07
    }
    DEF wall Solid {
      translation 0.5600020086913835 3.47999906408281 -0.018338271440969084
      rotation -1.0538368034241465e-08 9.88036031973833e-09 -0.9999999999999999 1.5707945073638403
      children [
        DEF wall Shape {
          appearance PBRAppearance {
            baseColor 0 0 0
          }
          geometry Box {
            size 0.1 1.5 0.4
          }
        }
      ]
      name "solid(7)"
      boundingObject USE wall
      physics Physics {
      }
      linearVelocity -6.725927747885879e-09 1.8935632075608063e-07 -7.107537505362653e-06
      angularVelocity 1.318138973002545e-11 -5.676442038912221e-11 -1.4219549869556288e-07
    }
    DEF wall Solid {
      translation 0.6454523834714587 5.088867902031802 -0.01834113083983302
      rotation 6.056946003554737e-09 4.755428835841971e-08 -0.9999999999999988 1.5697472988554306
      children [
        DEF wall Shape {
          appearance PBRAppearance {
            baseColor 0 0 0
          }
          geometry Box {
            size 0.1 1.5 0.4
          }
        }
      ]
      name "solid(6)"
      boundingObject USE wall
      physics Physics {
      }
      linearVelocity -1.402868698126742e-07 5.193339674382479e-06 -7.107272194177086e-06
      angularVelocity -3.656476500552817e-11 8.908171060528991e-11 -1.0748554679707846e-05
    }
    DEF wall Solid {
      translation 2.125459414305582 5.089999890807069 -0.018341183108382092
      rotation 5.4720535790447124e-09 4.6352678429088255e-09 -1 1.5708862456869708
      children [
        DEF wall Shape {
          appearance PBRAppearance {
            baseColor 0 0 0
          }
          geometry Box {
            size 0.1 1.5 0.4
          }
        }
      ]
      name "solid(8)"
      boundingObject USE wall
      physics Physics {
      }
      linearVelocity 3.0661950665414638e-06 1.2634969704405311e-06 -7.10749093298839e-06
      angularVelocity 5.315302061723108e-12 -2.3811048319293268e-11 -6.079694853327085e-06
    }
    DEF wall Solid {
      translation 2.9100755149079953 4.329940929371302 -0.018341184258588605
      rotation -1.0260443948471363e-08 -1.3533303318240876e-08 -0.9999999999999998 0.007410098395893321
      children [
        DEF wall Shape {
          appearance PBRAppearance {
            baseColor 0 0 0
          }
          geometry Box {
            size 0.1 1.5 0.4
          }
        }
      ]
      name "solid(9)"
      boundingObject USE wall
      physics Physics {
      }
      linearVelocity 6.958330170709815e-06 3.3149486113297644e-06 -7.1074629981011e-06
      angularVelocity -2.2547831259335117e-12 -2.608461873729706e-13 6.777359056738849e-07
    }
    DEF wall Solid {
      translation 2.9000404422881028 2.829937241695934 -0.018341184151068363
      rotation 2.339832608171854e-06 -1.2426740510044829e-08 -0.9999999999972625 3.8099876460703184e-05
      children [
        DEF wall Shape {
          appearance PBRAppearance {
            baseColor 0 0 0
          }
          geometry Box {
            size 0.1 1.5 0.4
          }
        }
      ]
      name "solid(10)"
      boundingObject USE wall
      physics Physics {
      }
      linearVelocity -3.3297696263700763e-06 5.6901276895381035e-08 -7.107465742895283e-06
      angularVelocity 5.72026460712364e-13 4.274682117174443e-13 3.503351878829115e-06
    }
    DEF wall Solid {
      translation 2.113264627033158 0.5300091520291758 -0.01833981127538664
      rotation -1.0257421372771778e-08 9.4541628283892e-09 -0.9999999999999998 1.5708227781538253
      children [
        DEF wall Shape {
          appearance PBRAppearance {
            baseColor 0 0 0
          }
          geometry Box {
            size 0.1 1.5 0.4
          }
        }
      ]
      name "solid(12)"
      boundingObject USE wall
      physics Physics {
      }
      linearVelocity 2.5701594913698903e-07 -3.8170761094300825e-07 -7.107458871663772e-06
      angularVelocity -3.8923818172952426e-13 -5.747320445655835e-12 -6.510121569901555e-07
    }
    DEF wall Solid {
      translation 0.6155764292392076 0.530005988778376 -0.01833978612698481
      rotation -3.228158193109467e-10 3.344485766353172e-10 -1 1.5707823091107516
      children [
        DEF wall Shape {
          appearance PBRAppearance {
            baseColor 0 0 0
          }
          geometry Box {
            size 0.1 1.5 0.4
          }
        }
      ]
      name "solid(15)"
      boundingObject USE wall
      physics Physics {
      }
      linearVelocity -6.983657740676469e-07 -2.3423613421097832e-07 -7.107460191339743e-06
      angularVelocity 3.220207524695656e-13 -1.2640576880571377e-12 -1.751142422173154e-07
    }
    DEF wall Solid {
      translation -0.9372954832770821 -0.9873887150478212 -0.018340030665556062
      rotation -2.1914296435983012e-09 2.1198427513362454e-09 -1 1.570398077899203
      children [
        DEF wall Shape {
          appearance PBRAppearance {
            baseColor 0 0 0
          }
          geometry Box {
            size 0.1 1.5 0.4
          }
        }
      ]
      name "solid(19)"
      boundingObject USE wall
      physics Physics {
      }
      linearVelocity -4.874494677162603e-05 3.2227616672100335e-05 -7.107463056308707e-06
      angularVelocity 1.2947954377808275e-13 -2.109462033721387e-12 2.8863989250479084e-05
    }
    DEF wall Solid {
      translation 0.5862947679947128 -0.9624538884675297 -0.01834003865189393
      rotation -2.014841284409871e-09 1.8073366166747022e-09 -1 1.5833444417747993
      children [
        DEF wall Shape {
          appearance PBRAppearance {
            baseColor 0 0 0
          }
          geometry Box {
            size 0.1 1.5 0.4
          }
        }
      ]
      name "solid(20)"
      boundingObject USE wall
      physics Physics {
      }
      linearVelocity -9.305908976952698e-05 2.3873494255591523e-06 -7.107462673896761e-06
      angularVelocity -4.0429381681422836e-14 -7.333980814874726e-13 -4.706497786345847e-06
    }
    DEF wall Solid {
      translation -0.15623871973201187 -1.7445981615456143 -0.018340030843789296
      rotation 3.429383581253251e-10 1.9556462818918993e-09 1 3.131247495768044
      children [
        DEF wall Shape {
          appearance PBRAppearance {
            baseColor 0 0 0
          }
          geometry Box {
            size 0.1 1.5 0.4
          }
        }
      ]
      name "solid(24)"
      boundingObject USE wall
      physics Physics {
      }
      linearVelocity 8.899924781104578e-05 -3.606553154146841e-05 -7.1074621838611325e-06
      angularVelocity -7.487505848561974e-14 -3.1000689205105274e-13 -6.585786074312794e-05
    }
    DEF wall Solid {
      translation 2.1099995758042054 -2.480000201744659 -0.018339785544806253
      rotation -7.224716262542709e-12 -4.9584214588588806e-11 1 1.5707951656956505
      children [
        DEF wall Shape {
          appearance PBRAppearance {
            baseColor 0 0 0
          }
          geometry Box {
            size 0.1 1.5 0.4
          }
        }
      ]
      name "solid(21)"
      boundingObject USE wall
      physics Physics {
      }
      linearVelocity 0 0 -7.1074621936225985e-06
    }
    DEF wall Solid {
      translation 2.910005010024409 -1.7300083301286824 -0.01833978473327319
      rotation 9.280852691473468e-12 -2.998372841873799e-10 1 3.1415864326978715
      children [
        DEF wall Shape {
          appearance PBRAppearance {
            baseColor 0 0 0
          }
          geometry Box {
            size 0.1 1.5 0.4
          }
        }
      ]
      name "solid(22)"
      boundingObject USE wall
      physics Physics {
      }
      linearVelocity -5.214973845752397e-07 6.790096889641333e-09 -7.107462260986388e-06
      angularVelocity -1.4261112213171588e-14 -3.346292479306138e-12 3.9107938576500027e-07
    }
    DEF wall Solid {
      translation 2.911153842253799 -0.23000805046679632 -0.01833977776148818
      rotation 3.270823871219068e-10 -3.4362950124620825e-09 1 3.1407421300312315
      children [
        DEF wall Shape {
          appearance PBRAppearance {
            baseColor 0 0 0
          }
          geometry Box {
            size 0.1 1.5 0.4
          }
        }
      ]
      name "solid(23)"
      boundingObject USE wall
      physics Physics {
      }
      linearVelocity 9.615680317194965e-07 6.397529027942699e-07 -7.107461428132357e-06
      angularVelocity 7.135469233466526e-13 3.58785381771247e-12 3.16281312864731e-08
    }
    DEF wall Solid {
      translation 0.5701230611335673 2.0701016872236173 -0.018340015224155154
      rotation 9.668429147839868e-12 -4.047136795302632e-12 -1 1.570911548356555
      children [
        DEF wall Shape {
          appearance PBRAppearance {
            baseColor 0 0 0
          }
          geometry Box {
            size 0.1 1.5 0.4
          }
        }
      ]
      name "solid(14)"
      boundingObject USE wall
      physics Physics {
      }
      linearVelocity 9.812823910616121e-07 -4.456510326938337e-06 -7.107462230851196e-06
      angularVelocity 2.8255567767331525e-14 -5.185765740396987e-14 5.996185006387975e-06
    }
    DEF wall Solid {
      translation -0.9230276405820304 2.0711136216824935 -0.018340015301182427
      rotation 7.145880401249984e-11 -8.408387330324376e-12 -1 1.5714666675832378
      children [
        DEF wall Shape {
          appearance PBRAppearance {
            baseColor 0 0 0
          }
          geometry Box {
            size 0.1 1.5 0.4
          }
        }
      ]
      name "solid(16)"
      boundingObject USE wall
      physics Physics {
      }
      linearVelocity 8.126572367663083e-07 -1.569481807555112e-05 -7.107462358909267e-06
      angularVelocity -1.884926120342663e-13 -2.0022823845000135e-13 2.1312780630456928e-05
    }
    DEF wall Solid {
      translation -1.7107410905908216 1.3042121116907446 -0.018340015939615872
      rotation 8.722748940341367e-08 4.974022869387551e-09 0.999999999999996 0.00890865428318756
      children [
        DEF wall Shape {
          appearance PBRAppearance {
            baseColor 0 0 0
          }
          geometry Box {
            size 0.1 1.5 0.4
          }
        }
      ]
      name "solid(17)"
      boundingObject USE wall
      physics Physics {
      }
      linearVelocity -7.112649883186361e-06 2.2492301921621036e-05 -7.107461220646346e-06
      angularVelocity -1.9694310120065144e-13 -1.8868635003172575e-13 -3.350377265305986e-07
    }
    DEF wall Solid {
      translation -1.7034647580406093 -0.19103069932294078 -0.018340020823727293
      rotation 3.835469101870713e-06 4.353373865022291e-07 -0.99999999999255 0.0013699748339318335
      children [
        DEF wall Shape {
          appearance PBRAppearance {
            baseColor 0 0 0
          }
          geometry Box {
            size 0.1 1.5 0.4
          }
        }
      ]
      name "solid(18)"
      boundingObject USE wall
      physics Physics {
      }
      linearVelocity 5.702927519740138e-05 8.750288676405193e-07 -7.107461615972349e-06
      angularVelocity -1.6721787235977519e-12 3.56648350817461e-13 3.647474404436281e-05
    }
    DEF wall Solid {
      translation 2.900003682773554 1.3299828133406335 -0.018341164723489317
      rotation -0.011777077528249821 0.0006656608432948203 -0.9999304262500142 1.0637189127589621e-06
      children [
        DEF wall Shape {
          appearance PBRAppearance {
            baseColor 0 0 0
          }
          geometry Box {
            size 0.1 1.5 0.4
          }
        }
      ]
      name "solid(13)"
      boundingObject USE wall
      physics Physics {
      }
      linearVelocity -6.701249242346309e-07 -3.9581801643147024e-08 -7.1074659600232344e-06
      angularVelocity 6.506831854843639e-12 -6.675656518151929e-13 5.057702553254731e-07
    }
    DEF wall Solid {
      translation 1.3643498424584601 2.7800444645946856 -0.018340015212234356
      rotation 3.722595178889923e-10 -1.6190116889002636e-10 1 0.003059279509852663
      children [
        DEF wall Shape {
          appearance PBRAppearance {
            baseColor 0 0 0
          }
          geometry Box {
            size 0.1 1.5 0.4
          }
        }
      ]
      name "solid(11)"
      boundingObject USE wall
      physics Physics {
      }
      linearVelocity 1.094223776728657e-06 -1.7654369439691547e-06 -7.10746220944828e-06
      angularVelocity 1.2849546309506348e-14 -6.06121750347198e-16 8.636628982343922e-07
    }
  ]
  name "solid(1)"
}
Solid {
  translation 1.1021563337658618 -2.7976900002780263 0.19960132404551031
  rotation -6.212791114562661e-08 0.9997269375563805 -0.023367719703406762 5.3190651796193865e-06
  children [
    DEF box Shape {
      appearance PBRAppearance {
        baseColor 1 0 0
        metalness 0
      }
      geometry Box {
        size 0.4 0.4 0.4
      }
    }
  ]
  boundingObject USE box
  physics Physics {
    mass 1
  }
  linearVelocity 1.3015857408581584e-10 -5.98085085146485e-17 -5.6843418860808095e-16
  angularVelocity 2.6645352591003776e-16 1.3322676295504572e-16 -1.019925924316061e-16
}
Solid {
  translation 0.10950300257181249 1.73239 0.19960659223500613
  rotation 1.6490074421127094e-08 0.9999807563477658 0.006203783857444814 5.317715074777263e-06
  children [
    DEF box Shape {
      appearance PBRAppearance {
        baseColor 1 0 0
        metalness 0
      }
      geometry Box {
        size 0.4 0.4 0.4
      }
    }
  ]
  name "solid(2)"
  boundingObject USE box
  physics Physics {
    mass 1
  }
  linearVelocity 1.301588877933172e-10 -2.3319603084485943e-17 -5.115907697472718e-16
  angularVelocity 6.661338147750948e-17 1.5987211554605597e-15 -1.2791383349666077e-17
}
Solid {
  translation 6.398096533401326 -0.7076100000447352 0.19957321753979143
  rotation 1.6470918512126896e-08 0.9999807979886561 0.0061970681753863955 5.317714853354801e-06
  children [
    DEF box Shape {
      appearance PBRAppearance {
        baseColor 1 0 0
        metalness 0
      }
      geometry Box {
        size 0.4 0.4 0.4
      }
    }
  ]
  name "solid(3)"
  boundingObject USE box
  physics Physics {
    mass 1
  }
  linearVelocity 1.301588310246541e-10 -2.7497020502545442e-17 -7.389644451905045e-16
  angularVelocity 1.998401444325281e-16 1.5321077739833549e-15 6.122269439459357e-17
}
Solid {
  translation 2.1095000025738595 5.16239 0.19959597789175462
  rotation 1.6493281224385534e-08 0.9999807563476959 0.006203783868717152 5.317715074792564e-06
  children [
    DEF box Shape {
      appearance PBRAppearance {
        baseColor 1 0 0
        metalness 0
      }
      geometry Box {
        size 0.4 0.4 0.4
      }
    }
  ]
  name "solid(4)"
  boundingObject USE box
  physics Physics {
    mass 1
  }
  linearVelocity 1.3015880878143331e-10 4.2983967622235715e-17 -4.547473508864645e-16
  angularVelocity -3.996802888650563e-16 1.3322676295499859e-15 -1.3825102358495242e-17
}
Solid {
  translation 1.6295027675497156 -0.7276100000000284 0.19959852532328193
  rotation 1.6494393520357345e-08 0.9999807609498673 0.006203042005668925 5.317715050520043e-06
  children [
    DEF box Shape {
      appearance PBRAppearance {
        baseColor 1 0 0
        metalness 0
      }
      geometry Box {
        size 0.4 0.4 0.4
      }
    }
  ]
  name "solid(5)"
  boundingObject USE box
  physics Physics {
    mass 1
  }
  linearVelocity 1.30158560222339e-10 4.183185373617132e-17 -6.821210263296965e-16
  angularVelocity -3.996802888650568e-16 1.99840144431696e-16 3.575071960476212e-17
}
Solid {
  translation -0.9205199995964154 -4.45761 0.19961205875205404
  rotation 1.6492479789931128e-08 0.9999807563483406 0.006203783764801316 5.317715074772952e-06
  children [
    DEF box Shape {
      appearance PBRAppearance {
        baseColor 1 0 0
        metalness 0
      }
      geometry Box {
        size 0.4 0.4 0.4
      }
    }
  ]
  name "solid(11)"
  boundingObject USE box
  physics Physics {
    mass 1
  }
  linearVelocity 1.301588615777423e-10 -3.343240398065439e-17 2.1657342585968125e-14
  angularVelocity 1.9984014443252813e-16 1.4654943925042236e-15 3.3288394827094e-17
}
Solid {
  translation 6.739480100581326 -4.45761 0.1995714057558925
  rotation 1.6494883966432725e-08 0.9999807563461277 0.0062037841215040294 5.317715074776227e-06
  children [
    DEF box Shape {
      appearance PBRAppearance {
        baseColor 1 0 0
        metalness 0
      }
      geometry Box {
        size 0.4 0.4 0.4
      }
    }
  ]
  name "solid(12)"
  boundingObject USE box
  physics Physics {
    mass 1
  }
  linearVelocity 1.3015884923957577e-10 -2.0790782832326437e-17 -5.684341886080803e-16
  angularVelocity 2.664535259100374e-16 1.5987211554600318e-15 1.504076404439461e-17
}
Solid {
  translation 5.799470046259248 -3.432344767363654 0.19957639455806395
  rotation 1.99547831464297e-07 0.997179969867751 0.07504736967083714 5.332650979150759e-06
  children [
    DEF box Shape {
      appearance PBRAppearance {
        baseColor 1 0 0
        metalness 0
      }
      geometry Box {
        size 0.4 0.4 0.4
      }
    }
  ]
  name "solid(10)"
  boundingObject USE box
  physics Physics {
    mass 1
  }
  linearVelocity 1.3015856599837155e-10 6.445829926673271e-17 -4.547473508864637e-16
  angularVelocity 2.662405555120915e-30 1.3322676295495358e-16 -4.053408406449658e-17
}
Solid {
  translation 3.4295000440736483 1.8500032545549332 0.19958897241448018
  rotation -4.865331958420343e-08 0.999832550244366 -0.018299493759248185 5.318503324576252e-06
  children [
    DEF box Shape {
      appearance PBRAppearance {
        baseColor 1 0 0
        metalness 0
      }
      geometry Box {
        size 0.4 0.4 0.4
      }
    }
  ]
  name "solid(6)"
  boundingObject USE box
  physics Physics {
    mass 1
  }
  linearVelocity 1.3015887259502533e-10 -4.4257105575804015e-17 -5.115907697472722e-16
  angularVelocity 2.664535259100375e-16 1.5987211554605353e-15 -1.1530744214267516e-16
}
Solid {
  translation 3.2295000024627054 -8.47761 0.1995900338506183
  rotation 1.6492078676760182e-08 0.9999807563477302 0.00620378386318541 5.317715074745466e-06
  children [
    DEF box Shape {
      appearance PBRAppearance {
        baseColor 1 0 0
        metalness 0
      }
      geometry Box {
        size 0.4 0.4 0.4
      }
    }
  ]
  name "solid(7)"
  boundingObject USE box
  physics Physics {
    mass 1
  }
  linearVelocity 1.301588238794907e-10 7.11132270691392e-18 -5.6843418860808e-16
  angularVelocity 6.661338147750945e-17 1.2656542480738237e-15 -2.825854377970851e-17
}
Solid {
  translation -3.671285110895356 -8.477609999505532 0.1996262959283699
  rotation 5.876876106903917e-09 0.9999999782720359 0.0002084608544030495 0.00015498517112318765
  children [
    DEF box Shape {
      appearance PBRAppearance {
        baseColor 1 0 0
        metalness 0
      }
      geometry Box {
        size 0.4 0.4 0.4
      }
    }
  ]
  name "solid(8)"
  boundingObject USE box
  physics Physics {
    mass 1
  }
  linearVelocity 3.378489205807967e-06 6.010715972122387e-14 7.03718097838646e-09
  angularVelocity 4.169997680492088e-13 -1.1215152859067604e-05 3.757962274697491e-11
}
Solid {
  translation -4.071194300967864 -8.47761000049446 0.19962913698560036
  rotation -7.2220171915565975e-09 -0.9999999743168108 0.00022664151776860978 0.00014794789193629652
  children [
    DEF box Shape {
      appearance PBRAppearance {
        baseColor 1 0 0
        metalness 0
      }
      geometry Box {
        size 0.4 0.4 0.4
      }
    }
  ]
  name "solid(9)"
  boundingObject USE box
  physics Physics {
    mass 1
  }
  linearVelocity -3.3648207065049006e-06 -6.53445338618625e-14 -6.354919207751663e-09
  angularVelocity -3.789810913007449e-13 1.1282193764827754e-05 -3.822122618402089e-11
}
Robot {
  translation 3.730376799780592 -1.9442578426512802 0.07200448974187515
  rotation -0.32276081908709203 -0.8649577648579617 -0.38428312306702794 1.7062972283762716
  children [
    Solid {
      rotation 0.5773502691896258 0.5773502691896258 0.5773502691896258 0
      children [
        Hinge2Joint {
          jointParameters HingeJointParameters {
            position 0.044048720668305064
            anchor 0 0.13 0
          }
          jointParameters2 JointParameters {
            position 0.07321146419391483
          }
          device [
            RotationalMotor {
              name "link1"
            }
          ]
          device2 [
            RotationalMotor {
              name "link12"
            }
          ]
          endPoint Solid {
            translation -0.0011837284929750946 0.1353932259764259 -0.010640878011050105
            rotation 0.4984180844369927 0.12905910826974887 0.8572765946173826 0.08570838991133192
            children [
              DEF Encoders Hinge2Joint {
                jointParameters HingeJointParameters {
                }
                jointParameters2 JointParameters {
                }
                device [
                  PositionSensor {
                    name "link1Encoder"
                  }
                ]
                device2 [
                  PositionSensor {
                    name "link12Encoder"
                  }
                ]
              }
              Solid {
                translation -1.87158e-08 0.09 0.01
                rotation 3.390508950807168e-09 0.70710578118615 0.707107781185531 3.14159
                children [
                  DistanceSensor {
                    translation -0.071126 0.00746591 -0.0137034
                    rotation 0.5745980014348747 0.816664002039357 0.053824200134408716 3.0945
                    children [
                      DEF ds Shape {
                        appearance PBRAppearance {
                          metalness 0
                        }
                        geometry Box {
                          size 0.02 0.02 0.02
                        }
                      }
                    ]
                    name "frontRightDs"
                    boundingObject USE ds
                    physics Physics {
                    }
                    lookupTable [
                      0 0 0
                      1 1000 0
                    ]
                    numberOfRays 12
                    aperture 0.3
                  }
                  DistanceSensor {
                    translation -0.0662512 -0.0190048 -0.0112132
                    rotation 0.4884917695565045 -0.32440084696555854 -0.8100246178750268 2.17555
                    children [
                      DEF ds Shape {
                        appearance PBRAppearance {
                          metalness 0
                        }
                        geometry Box {
                          size 0.02 0.02 0.02
                        }
                      }
                    ]
                    name "frontLeftDs"
                    boundingObject USE ds
                    physics Physics {
                    }
                    lookupTable [
                      0 0 0
                      1 1000 0
                    ]
                    numberOfRays 12
                    aperture 0.3
                  }
                  TouchSensor {
                    translation -0.001883420832871907 0.002788041653797535 0.007109095744006089
                    rotation -0.014918636683969819 -0.010808006026690459 -0.9998302962429269 0.5137363817830749
                    children [
                      DEF segment Shape {
                        geometry Cylinder {
                          height 0.1
                          radius 0.075
                        }
                      }
                    ]
                    name "segment1TouchSensor"
                    boundingObject USE segment
                    physics Physics {
                    }
                    linearVelocity -0.007845377271517396 0.015898521570311217 -0.001245198420443197
                    angularVelocity -0.4271442374329912 -0.18525357277438492 -1.6554687539635242
                  }
                  Hinge2Joint {
                    jointParameters HingeJointParameters {
                      position 0.038665134851605845
                      anchor 0 0 0.08
                    }
                    jointParameters2 JointParameters {
                      position -0.15573926112866904
                    }
                    device [
                      RotationalMotor {
                        name "link2"
                      }
                    ]
                    device2 [
                      RotationalMotor {
                        name "link22"
                      }
                    ]
                    endPoint Solid {
                      translation 0.00012534802006763766 0.0003340430330210188 0.08604486151907431
                      rotation 0.25435580929211493 0.11166445263268386 -0.9606425830128479 0.16179302386204533
                      children [
                        DEF encoders Hinge2Joint {
                          jointParameters HingeJointParameters {
                          }
                          jointParameters2 JointParameters {
                          }
                          device [
                            PositionSensor {
                              name "link2Encoder"
                            }
                          ]
                          device2 [
                            PositionSensor {
                              name "link22Encoder"
                            }
                          ]
                        }
                        Solid {
                          translation 0 0 0.09
                          children [
                            Solid {
                              translation -0.14 0 5.14248e-07
                              rotation 0 1 0 1.5708
                              children [
                                Camera {
                                  translation 0 5.30718e-08 -0.1
                                  rotation 4.7949e-09 -1 1.32679e-06 3.14159
                                  name "rearCamera"
                                  recognitionColors [
                                    1 0 0
                                  ]
                                  fieldOfView 0.78
                                  width 128
                                  height 128
                                  antiAliasing TRUE
                                  recognition Recognition {
                                    frameColor 0 1 0
                                  }
                                }
                                Camera {
                                  translation 0 5.30718e-08 -0.1
                                  rotation -0.7071067811862364 -0.7071067811862364 9.381857096790023e-07 3.14159
                                  name "rightCamera"
                                  recognitionColors [
                                    1 0 0
                                  ]
                                  fieldOfView 0.78
                                  width 128
                                  height 128
                                  antiAliasing TRUE
                                  recognition Recognition {
                                  }
                                }
                                Camera {
                                  translation 0 5.30718e-08 -0.1
                                  rotation 0.7071067811862364 -0.7071067811862364 9.381857096790023e-07 3.14159
                                  name "leftCamera"
                                  recognitionColors [
                                    0 0 0
                                  ]
                                  fieldOfView 0.78
                                  width 128
                                  height 128
                                  antiAliasing TRUE
                                  recognition Recognition {
                                    frameThickness 3
                                  }
                                }
                                Camera {
                                  translation 0 5.30718e-08 -0.1
                                  rotation 1 0 0 3.14159
                                  name "frontCamera"
                                  recognitionColors [
                                    0 0 0
                                  ]
                                  fieldOfView 0.78
                                  width 128
                                  height 128
                                  antiAliasing TRUE
                                  recognition Recognition {
                                  }
                                }
                                DEF pole Shape {
                                  appearance PBRAppearance {
                                    baseColor 1 0 0
                                    metalness 0
                                  }
                                  geometry Capsule {
                                    height 0.2
                                    radius 0.01
                                  }
                                }
                              ]
                              name "solid(1)"
                              boundingObject USE pole
                              physics Physics {
                              }
                            }
                            TouchSensor {
                              translation 0.000704080476189195 0.0006454560578159629 0.0032508169297502665
                              rotation 0.3085199506301623 0.375801649564223 0.873835545310427 0.000959815263319209
                              name "segment2TouchSensor"
                              boundingObject USE segment
                              physics Physics {
                              }
                              linearVelocity 0.011677307533428504 0.0004613622343087459 -0.018938494910240012
                              angularVelocity -0.4520528532133172 -0.3791919165006328 1.0084647378983824
                            }
                            RangeFinder {
                              translation -0.058508 -0.0234795 0
                              rotation 0 0 1 -2.3561953071795863
                              children [
                                DEF rangeFinder Shape {
                                  appearance PBRAppearance {
                                    baseColor 0 0.6 0
                                  }
                                  geometry Box {
                                    size 0.05 0.05 0.05
                                  }
                                }
                              ]
                              name "leftRangeFinder"
                              boundingObject USE rangeFinder
                              physics Physics {
                              }
                            }
                            RangeFinder {
                              translation -0.0565345 0.0250965 0
                              rotation 0 0 1 2.3562
                              children [
                                DEF rangeFinder Shape {
                                  appearance PBRAppearance {
                                    baseColor 0 0.6 0
                                  }
                                  geometry Box {
                                    size 0.05 0.05 0.05
                                  }
                                }
                              ]
                              name "rightRangeFinder"
                              boundingObject USE rangeFinder
                              physics Physics {
                              }
                            }
                            Hinge2Joint {
                              jointParameters HingeJointParameters {
                                position 0.284611743008732
                                anchor 0 0 0.08
                              }
                              jointParameters2 JointParameters {
                                position 0.1200998007634062
                              }
                              device [
                                RotationalMotor {
                                  name "link3"
                                }
                              ]
                              device2 [
                                RotationalMotor {
                                  name "link32"
                                }
                              ]
                              endPoint Solid {
                                translation -0.0009435574251878653 -0.002056160340052005 0.08866845165217933
                                rotation 0.9188918333720014 -0.1143227937649692 0.3775819081841904 0.30898741687955616
                                children [
                                  DEF encoders Hinge2Joint {
                                    jointParameters HingeJointParameters {
                                    }
                                    jointParameters2 JointParameters {
                                    }
                                    device [
                                      PositionSensor {
                                        name "link3Encoder"
                                      }
                                    ]
                                    device2 [
                                      PositionSensor {
                                        name "link32Encoder"
                                      }
                                    ]
                                  }
                                  Solid {
                                    translation 0 0 0.09
                                    children [
                                      DistanceSensor {
                                        translation -0.0719313 -0.0078862 0.0237971
                                        rotation -0.42771792078365434 0.6899988722073908 0.5839168918545142 -2.3762053071795863
                                        children [
                                          DEF ds Shape {
                                            appearance PBRAppearance {
                                              metalness 0
                                            }
                                            geometry Box {
                                              size 0.02 0.02 0.02
                                            }
                                          }
                                        ]
                                        name "backLeftDs"
                                        boundingObject USE ds
                                        physics Physics {
                                        }
                                        lookupTable [
                                          0 0 0
                                          1 1000 0
                                        ]
                                        numberOfRays 12
                                        aperture 0.3
                                      }
                                      DistanceSensor {
                                        translation -0.0708338 0.00845135 0.025653
                                        rotation 0.7406046362064972 0.6710526703712216 -0.03454108303302333 -2.854285307179586
                                        children [
                                          DEF ds Shape {
                                            appearance PBRAppearance {
                                              metalness 0
                                            }
                                            geometry Box {
                                              size 0.02 0.02 0.02
                                            }
                                          }
                                        ]
                                        name "backRightDs"
                                        boundingObject USE ds
                                        physics Physics {
                                        }
                                        lookupTable [
                                          0 0 0
                                          1 1000 0
                                        ]
                                        numberOfRays 12
                                        aperture 0.3
                                      }
                                      TouchSensor {
                                        translation -0.0010995216462786617 -0.0002595610933786574 0.005971949945759114
                                        rotation -0.9731131683280805 -0.19279449696036505 -0.12602001257056333 -0.0012018617980453783
                                        name "segment3TouchSensor"
                                        boundingObject USE segment
                                        physics Physics {
                                        }
                                        linearVelocity -0.05026563917791248 0.05895335526314495 -0.005003888977915352
                                        angularVelocity -0.8773921329695344 -0.7282742019710042 0.02628826444401268
                                      }
                                      Hinge2Joint {
                                        jointParameters HingeJointParameters {
                                          position 0.007213244438522823
                                          anchor 0 0 0.08
                                        }
                                        jointParameters2 JointParameters {
                                          position -0.1541365748209785
                                        }
                                        device [
                                          RotationalMotor {
                                            name "link4"
                                          }
                                        ]
                                        device2 [
                                          RotationalMotor {
                                            name "link42"
                                          }
                                        ]
                                        endPoint Solid {
                                          translation -0.00023528060664865106 3.784699972655507e-05 0.08326159930442598
                                          rotation 0.04465420204654447 -0.004933005174481162 -0.9989903241270833 0.15429639398351153
                                          children [
                                            DEF encoders Hinge2Joint {
                                              jointParameters HingeJointParameters {
                                              }
                                              jointParameters2 JointParameters {
                                              }
                                              device [
                                                PositionSensor {
                                                  name "link4Encoder"
                                                }
                                              ]
                                              device2 [
                                                PositionSensor {
                                                  name "link42Encoder"
                                                }
                                              ]
                                            }
                                            Solid {
                                              translation 0 0 0.08
                                              children [
                                                RangeFinder {
                                                  translation -0.0775204 0.0214102 0.0141602
                                                  rotation -0.3033810254019426 -0.6841660572848843 -0.6632320555320907 2.4962
                                                  children [
                                                    DEF rangeFinder Shape {
                                                      appearance PBRAppearance {
                                                        baseColor 0 0.6 0
                                                      }
                                                      geometry Box {
                                                        size 0.05 0.05 0.05
                                                      }
                                                    }
                                                  ]
                                                  name "backRangeFinder"
                                                  boundingObject USE rangeFinder
                                                  physics Physics {
                                                  }
                                                }
                                                TouchSensor {
                                                  translation 0.008522886536307728 0.002664597373995381 -0.019170676500021244
                                                  rotation -0.08122483819617621 0.7444381060443782 0.6627325493206623 -0.00010094837330143491
                                                  name "segment4TouchSensor"
                                                  boundingObject USE segment
                                                  physics Physics {
                                                  }
                                                  linearVelocity -0.11479170138746894 0.17802781646997207 0.02592429234710206
                                                  angularVelocity -1.0528061744340738 -0.8998287011252261 2.2231428728377765
                                                }
                                                Solid {
                                                  translation 0 0 0.05
                                                  children [
                                                    DEF tail Shape {
                                                      appearance PBRAppearance {
                                                        baseColor 0 0 0
                                                        metalness 0
                                                      }
                                                      geometry Sphere {
                                                        radius 0.075
                                                      }
                                                    }
                                                  ]
                                                  boundingObject USE tail
                                                  physics Physics {
                                                  }
                                                }
                                                DEF segment Shape {
                                                  appearance PBRAppearance {
                                                    baseColor 0 1 0
                                                    metalness 0
                                                  }
                                                  geometry Cylinder {
                                                    height 0.1
                                                    radius 0.075
                                                  }
                                                }
                                              ]
                                              boundingObject USE segment
                                              physics Physics {
                                              }
                                            }
                                            DEF joint Shape {
                                              appearance PBRAppearance {
                                                baseColor 0 1 0
                                                metalness 0
                                              }
                                              geometry Sphere {
                                                radius 0.05
                                              }
                                            }
                                          ]
                                          boundingObject USE joint
                                          physics Physics {
                                          }
                                          linearVelocity -0.15413174058844215 0.251984173580898 0.03663306986606983
                                          angularVelocity -1.052749656261922 -0.8998299430435066 2.2231561580017005
                                        }
                                      }
                                      DEF segment Shape {
                                        appearance PBRAppearance {
                                          baseColor 0 1 0
                                          metalness 0
                                        }
                                        geometry Cylinder {
                                          height 0.1
                                          radius 0.075
                                        }
                                      }
                                    ]
                                    boundingObject USE segment
                                    physics Physics {
                                    }
                                  }
                                  DEF joint Shape {
                                    appearance PBRAppearance {
                                      baseColor 0 1 0
                                      metalness 0
                                    }
                                    geometry Sphere {
                                      radius 0.05
                                    }
                                  }
                                ]
                                boundingObject USE joint
                                physics Physics {
                                }
                                linearVelocity -0.048133788906101954 0.05777236706134039 -0.009954874533822473
                                angularVelocity -0.8773967731422909 -0.7282937726206827 0.026297312086768207
                              }
                            }
                            DEF segment Shape {
                              appearance PBRAppearance {
                                baseColor 0 1 0
                                metalness 0
                              }
                              geometry Cylinder {
                                height 0.1
                                radius 0.075
                              }
                            }
                          ]
                          boundingObject USE segment
                          physics Physics {
                          }
                        }
                        DEF link Shape {
                          appearance PBRAppearance {
                            baseColor 0 1 0
                            metalness 0
                          }
                          geometry Sphere {
                            radius 0.05
                          }
                        }
                      ]
                      boundingObject USE link
                      physics Physics {
                      }
                      linearVelocity 0.02266544638375368 -0.009746558954556256 -0.01881963309139551
                      angularVelocity -0.4520201101296735 -0.37921949225873586 1.0084815406546703
                    }
                  }
                  DEF segment Shape {
                    appearance PBRAppearance {
                      baseColor 0 1 0
                      metalness 0
                    }
                    geometry Cylinder {
                      height 0.1
                      radius 0.075
                    }
                  }
                ]
                boundingObject USE segment
                physics Physics {
                }
              }
              DEF joint Shape {
                appearance PBRAppearance {
                  baseColor 0 1 0
                  metalness 0
                }
                geometry Sphere {
                  radius 0.05
                }
              }
            ]
            name "solid(1)"
            boundingObject USE joint
            physics Physics {
            }
            linearVelocity -0.048004394010297935 0.03857869636300686 0.00614810348154126
            angularVelocity -0.4271436129755699 -0.18525300249296817 -1.6554690143475326
          }
        }
        DEF neck Solid {
          translation 0 0.05 9.99998e-08
          rotation -1 0 0 1.5708
          children [
            TouchSensor {
              translation -0.0014756525614351423 -0.008108805852570455 0.0006635217406114613
              rotation -0.6115324929457667 0.4380029354214925 -0.6589244559383811 -0.2112103746564804
              name "neckTouchSensor"
              boundingObject USE segment
              physics Physics {
              }
              linearVelocity -0.0814359682189912 0.054665946742449165 0.003175415696784402
              angularVelocity -0.3188463540572215 -0.4891761821726328 1.0725025274702644
            }
            Compass {
            }
            InertialUnit {
              name "imu"
              boundingObject USE segment
              physics Physics {
              }
            }
            GPS {
            }
            RangeFinder {
              translation 0.0486092 0.0130347 -0.0844306
              rotation 0.8429630744256347 0.2626550231899444 -0.4694950414519538 2.23099
              children [
                DEF rangeFinder Shape {
                  appearance PBRAppearance {
                    baseColor 0 0.6 0
                  }
                  geometry Box {
                    size 0.05 0.05 0.05
                  }
                }
              ]
              name "rangeFinder"
              boundingObject USE rangeFinder
              physics Physics {
              }
            }
            DEF neck Shape {
              appearance PBRAppearance {
                baseColor 0 0.8 0
                metalness 0
              }
              geometry Cylinder {
                height 0.1
                radius 0.075
              }
            }
          ]
          name "neck"
          boundingObject USE neck
          physics Physics {
          }
        }
        DEF head Shape {
          appearance PBRAppearance {
            baseColor 0 0.6 0
            metalness 0
          }
          geometry Sphere {
            radius 0.075
          }
        }
      ]
      name "snakeBot"
      boundingObject USE head
      physics Physics {
      }
    }
  ]
  name "SnakeBot"
  boundingObject USE head
  physics Physics {
  }
  controller "first_controller"
  linearVelocity -0.05517833185246919 0.04097172330680931 0.004368207004245469
  angularVelocity -0.3188421716117039 -0.48916159196946984 1.072510366607284
}
