#VRML_SIM R2023b utf8

EXTERNPROTO "https://raw.githubusercontent.com/cyberbotics/webots/R2023b/projects/objects/backgrounds/protos/TexturedBackground.proto"
EXTERNPROTO "https://raw.githubusercontent.com/cyberbotics/webots/R2023b/projects/objects/backgrounds/protos/TexturedBackgroundLight.proto"
EXTERNPROTO "https://raw.githubusercontent.com/cyberbotics/webots/R2023b/projects/objects/floors/protos/RectangleArena.proto"

WorldInfo {
}
Viewpoint {
  orientation -0.15642491932615313 0.8994621924968998 0.4080429007867632 1.1557357820559884
  position -2.4340301120316905 -4.093502177257925 12.5881416389402
}
TexturedBackground {
}
TexturedBackgroundLight {
}
RectangleArena {
  translation -2.32 -2.08 1.18885e-05
  rotation 0 -1 0 -5.307179586466759e-06
  floorSize 20 20
  floorTileSize 1 1
  wallHeight 0.6
}
DEF maze Solid {
  translation -10.6 -0.09 0.2
  children [
    DEF wall Solid {
      translation -1.7300616198624095 7.267029395358842 -0.016486155094816324
      rotation -0.010449252434613235 0.9791100605495224 -0.2030623117524962 1.0471955665324256e-05
      children [
        DEF wall Shape {
          appearance PBRAppearance {
            baseColor 0 0 0
          }
          geometry Box {
            size 0.1 1.5 0.4
          }
        }
      ]
      boundingObject USE wall
      physics Physics {
      }
    }
    DEF wall Solid {
      translation -0.09282393016488655 7.274666799603712 -0.01645951624992087
      rotation 0.00023018412935815784 0.00019980787256761005 -0.9999999535460391 0.0021612249175289506
      children [
        DEF wall Shape {
          appearance PBRAppearance {
            baseColor 0 0 0
          }
          geometry Box {
            size 0.1 1.5 0.4
          }
        }
      ]
      name "solid(1)"
      boundingObject USE wall
      physics Physics {
      }
    }
    DEF wall Solid {
      translation -0.11654114506235302 5.776540007681895 -0.01645955245009703
      rotation -2.0004402405930355e-05 -1.895452974240609e-05 -0.9999999996202749 0.022325337339771975
      children [
        DEF wall Shape {
          appearance PBRAppearance {
            baseColor 0 0 0
          }
          geometry Box {
            size 0.1 1.5 0.4
          }
        }
      ]
      name "solid(2)"
      boundingObject USE wall
      physics Physics {
      }
    }
    DEF wall Solid {
      translation -1.7300110169059284 5.774662409661744 -0.016460080719153336
      rotation -0.40447329500279633 -0.037896847227018166 0.9137642926925045 6.0078057029772575e-06
      children [
        DEF wall Shape {
          appearance PBRAppearance {
            baseColor 0 0 0
          }
          geometry Box {
            size 0.1 1.5 0.4
          }
        }
      ]
      name "solid(3)"
      boundingObject USE wall
      physics Physics {
      }
    }
    DEF wall Solid {
      translation -1.7300025897772464 4.278580534821616 -0.01645626247082929
      rotation 0.046203499061764554 -0.004755073633852421 0.9989207305633346 8.22596688796544e-06
      children [
        DEF wall Shape {
          appearance PBRAppearance {
            baseColor 0 0 0
          }
          geometry Box {
            size 0.1 1.5 0.4
          }
        }
      ]
      name "solid(4)"
      boundingObject USE wall
      physics Physics {
      }
    }
    DEF wall Solid {
      translation -0.9399970393885244 3.479714198395354 -0.01645667472263554
      rotation 3.7877957435658274e-08 -3.811547627566963e-08 -0.9999999999999986 1.570581784360113
      children [
        DEF wall Shape {
          appearance PBRAppearance {
            baseColor 0 0 0
          }
          geometry Box {
            size 0.1 1.5 0.4
          }
        }
      ]
      name "solid(5)"
      boundingObject USE wall
      physics Physics {
      }
    }
    DEF wall Solid {
      translation 0.5600014495092758 3.4799994044389013 -0.01645658646252518
      rotation 4.907396752598901e-10 4.553771862358757e-10 -1 1.5707947905121047
      children [
        DEF wall Shape {
          appearance PBRAppearance {
            baseColor 0 0 0
          }
          geometry Box {
            size 0.1 1.5 0.4
          }
        }
      ]
      name "solid(7)"
      boundingObject USE wall
      physics Physics {
      }
    }
    DEF wall Solid {
      translation 0.6453998114689163 5.088925925556997 -0.016459418801152786
      rotation 5.480494373695229e-09 4.8137713934395835e-08 -0.9999999999999989 1.5697990951934788
      children [
        DEF wall Shape {
          appearance PBRAppearance {
            baseColor 0 0 0
          }
          geometry Box {
            size 0.1 1.5 0.4
          }
        }
      ]
      name "solid(6)"
      boundingObject USE wall
      physics Physics {
      }
    }
    DEF wall Solid {
      translation 2.124650198704529 5.0899936475473195 -0.016459471126629932
      rotation 5.61960779386006e-09 4.492875691652627e-09 -1 1.5708777060294923
      children [
        DEF wall Shape {
          appearance PBRAppearance {
            baseColor 0 0 0
          }
          geometry Box {
            size 0.1 1.5 0.4
          }
        }
      ]
      name "solid(8)"
      boundingObject USE wall
      physics Physics {
      }
    }
    DEF wall Solid {
      translation 2.9092749675534693 4.329942132939662 -0.016459471752699156
      rotation -6.689229475297564e-08 -1.7736567909760157e-08 -0.9999999999999976 0.00682025884679178
      children [
        DEF wall Shape {
          appearance PBRAppearance {
            baseColor 0 0 0
          }
          geometry Box {
            size 0.1 1.5 0.4
          }
        }
      ]
      name "solid(9)"
      boundingObject USE wall
      physics Physics {
      }
    }
    DEF wall Solid {
      translation 2.900036264872737 2.829947057989949 -0.016459471154209565
      rotation -3.258877452965879e-05 1.6705399629754826e-06 -0.9999999994675906 3.408538724724964e-05
      children [
        DEF wall Shape {
          appearance PBRAppearance {
            baseColor 0 0 0
          }
          geometry Box {
            size 0.1 1.5 0.4
          }
        }
      ]
      name "solid(10)"
      boundingObject USE wall
      physics Physics {
      }
    }
    DEF wall Solid {
      translation 2.1133426380202422 0.5300091440820537 -0.01645804361202194
      rotation 1.2328123795263042e-08 -1.1348284476558194e-08 -0.9999999999999999 1.5708263349471867
      children [
        DEF wall Shape {
          appearance PBRAppearance {
            baseColor 0 0 0
          }
          geometry Box {
            size 0.1 1.5 0.4
          }
        }
      ]
      name "solid(12)"
      boundingObject USE wall
      physics Physics {
      }
    }
    DEF wall Solid {
      translation 0.6155996010068634 0.5300058549400151 -0.016458072554635134
      rotation 3.452324659737058e-10 -3.643995626083046e-10 -1 1.5707760390946033
      children [
        DEF wall Shape {
          appearance PBRAppearance {
            baseColor 0 0 0
          }
          geometry Box {
            size 0.1 1.5 0.4
          }
        }
      ]
      name "solid(15)"
      boundingObject USE wall
      physics Physics {
      }
    }
    DEF wall Solid {
      translation -0.9365103973295312 -0.987021562364078 -0.0164583185876854
      rotation -2.2023397175149357e-09 2.1128209538166374e-09 -1 1.570501570042543
      children [
        DEF wall Shape {
          appearance PBRAppearance {
            baseColor 0 0 0
          }
          geometry Box {
            size 0.1 1.5 0.4
          }
        }
      ]
      name "solid(19)"
      boundingObject USE wall
      physics Physics {
      }
    }
    DEF wall Solid {
      translation 0.586025079155057 -0.9631720189667049 -0.016458326570291754
      rotation -2.0076443428548036e-09 1.8136191103978145e-09 -1 1.5828377435775636
      children [
        DEF wall Shape {
          appearance PBRAppearance {
            baseColor 0 0 0
          }
          geometry Box {
            size 0.1 1.5 0.4
          }
        }
      ]
      name "solid(20)"
      boundingObject USE wall
      physics Physics {
      }
    }
    DEF wall Solid {
      translation -0.15690669851332117 -1.7439689383513048 -0.01645831876032916
      rotation 3.3754544138755954e-10 1.9600345915623364e-09 1 3.1317490751587136
      children [
        DEF wall Shape {
          appearance PBRAppearance {
            baseColor 0 0 0
          }
          geometry Box {
            size 0.1 1.5 0.4
          }
        }
      ]
      name "solid(24)"
      boundingObject USE wall
      physics Physics {
      }
    }
    DEF wall Solid {
      translation 2.1099995770856683 -2.480000201814832 -0.01645807346223227
      rotation -7.231588833188696e-12 -4.959130617321211e-11 1 1.5707951656430366
      children [
        DEF wall Shape {
          appearance PBRAppearance {
            baseColor 0 0 0
          }
          geometry Box {
            size 0.1 1.5 0.4
          }
        }
      ]
      name "solid(21)"
      boundingObject USE wall
      physics Physics {
      }
    }
    DEF wall Solid {
      translation 2.9100043648430356 -1.7300068181574437 -0.016458074637537706
      rotation 5.8147863419241476e-11 4.648969304394227e-10 1 3.1415869901830127
      children [
        DEF wall Shape {
          appearance PBRAppearance {
            baseColor 0 0 0
          }
          geometry Box {
            size 0.1 1.5 0.4
          }
        }
      ]
      name "solid(22)"
      boundingObject USE wall
      physics Physics {
      }
    }
    DEF wall Solid {
      translation 2.9110537472713274 -0.23000872676923947 -0.016458079510230567
      rotation -2.2015846267768103e-10 3.0655109808019437e-09 1 3.1408160128572495
      children [
        DEF wall Shape {
          appearance PBRAppearance {
            baseColor 0 0 0
          }
          geometry Box {
            size 0.1 1.5 0.4
          }
        }
      ]
      name "solid(23)"
      boundingObject USE wall
      physics Physics {
      }
    }
    DEF wall Solid {
      translation 0.5698536616152321 2.07009480496194 -0.016458303141446445
      rotation 1.1252170241844578e-11 -5.6077573721962794e-12 -1 1.570903116655712
      children [
        DEF wall Shape {
          appearance PBRAppearance {
            baseColor 0 0 0
          }
          geometry Box {
            size 0.1 1.5 0.4
          }
        }
      ]
      name "solid(14)"
      boundingObject USE wall
      physics Physics {
      }
    }
    DEF wall Solid {
      translation -0.9233117581570323 2.0710183875558337 -0.01645830322076014
      rotation 7.366077468086035e-11 -1.059299993044969e-11 -0.9999999999999999 1.5714024792037597
      children [
        DEF wall Shape {
          appearance PBRAppearance {
            baseColor 0 0 0
          }
          geometry Box {
            size 0.1 1.5 0.4
          }
        }
      ]
      name "solid(16)"
      boundingObject USE wall
      physics Physics {
      }
    }
    DEF wall Solid {
      translation -1.7099501067919096 1.303933665534552 -0.016458303853726874
      rotation 9.240882135782726e-08 5.807453054423604e-09 0.9999999999999958 0.008248890020809299
      children [
        DEF wall Shape {
          appearance PBRAppearance {
            baseColor 0 0 0
          }
          geometry Box {
            size 0.1 1.5 0.4
          }
        }
      ]
      name "solid(17)"
      boundingObject USE wall
      physics Physics {
      }
    }
    DEF wall Solid {
      translation -1.7032598816052253 -0.19092499776151775 -0.016458308738041744
      rotation 4.041973515027664e-06 4.5665413732754666e-07 -0.9999999999917268 0.001305771507499468
      children [
        DEF wall Shape {
          appearance PBRAppearance {
            baseColor 0 0 0
          }
          geometry Box {
            size 0.1 1.5 0.4
          }
        }
      ]
      name "solid(18)"
      boundingObject USE wall
      physics Physics {
      }
    }
    DEF wall Solid {
      translation 2.900003004551575 1.3299844315580907 -0.016459495269470853
      rotation 0.015294090527062936 -0.0007950381972807849 -0.9998827224775989 1.114629407161221e-06
      children [
        DEF wall Shape {
          appearance PBRAppearance {
            baseColor 0 0 0
          }
          geometry Box {
            size 0.1 1.5 0.4
          }
        }
      ]
      name "solid(13)"
      boundingObject USE wall
      physics Physics {
      }
    }
    DEF wall Solid {
      translation 1.364060080990912 2.7800410801989153 -0.016458303129150142
      rotation 2.754208740974051e-10 1.3031359200430286e-09 1 0.0028557901123933663
      children [
        DEF wall Shape {
          appearance PBRAppearance {
            baseColor 0 0 0
          }
          geometry Box {
            size 0.1 1.5 0.4
          }
        }
      ]
      name "solid(11)"
      boundingObject USE wall
      physics Physics {
      }
    }
  ]
  name "solid(1)"
}
Solid {
  translation 0.10950300271970968 -5.72761 0.19960659475309764
  rotation 1.6490074448090403e-08 0.9999807563478172 0.006203783849164063 5.317715073182494e-06
  children [
    DEF box Shape {
      appearance PBRAppearance {
        baseColor 1 0 0
        metalness 0
      }
      geometry Box {
        size 0.4 0.4 0.4
      }
    }
  ]
  boundingObject USE box
  physics Physics {
    mass 1
  }
}
Solid {
  translation -1.420499999465908 1.38239 0.19961471475379813
  rotation 1.6500095823864094e-08 0.9999807563478682 0.006203783840964872 5.317715073188625e-06
  children [
    DEF box Shape {
      appearance PBRAppearance {
        baseColor 1 0 0
        metalness 0
      }
      geometry Box {
        size 0.4 0.4 0.4
      }
    }
  ]
  name "solid(2)"
  boundingObject USE box
  physics Physics {
    mass 1
  }
}
Solid {
  translation -2.2196499994168635 -0.178034 0.1996189559863644
  rotation 2.6483324841891444e-06 0.08867134853698236 0.9960609378655603 5.996990941292564e-05
  children [
    DEF box Shape {
      appearance PBRAppearance {
        baseColor 1 0 0
        metalness 0
      }
      geometry Box {
        size 0.4 0.4 0.4
      }
    }
  ]
  name "solid(3)"
  boundingObject USE box
  physics Physics {
    mass 1
  }
}
Solid {
  translation 3.8195 4.30239 0.199596
  rotation 1.649007447883058e-08 0.999980756347889 0.006203783837593294 5.317715073190637e-06
  children [
    DEF box Shape {
      appearance PBRAppearance {
        baseColor 1 0 0
        metalness 0
      }
      geometry Box {
        size 0.4 0.4 0.4
      }
    }
  ]
  name "solid(4)"
  boundingObject USE box
  physics Physics {
    mass 1
  }
}
Solid {
  translation 2.50962 0.74204 0.199594
  rotation 1.4004733863618816e-08 0.9999861291588888 0.005267019064119426 5.317686503499757e-06
  children [
    DEF box Shape {
      appearance PBRAppearance {
        baseColor 1 0 0
        metalness 0
      }
      geometry Box {
        size 0.4 0.4 0.4
      }
    }
  ]
  name "solid(5)"
  boundingObject USE box
  physics Physics {
    mass 1
  }
}
Solid {
  translation 0.34950000498666517 -2.44761 0.19960532104590636
  rotation 1.649528577965253e-08 0.9999807563483479 0.006203783763616118 5.31771507317541e-06
  children [
    DEF box Shape {
      appearance PBRAppearance {
        baseColor 1 0 0
        metalness 0
      }
      geometry Box {
        size 0.4 0.4 0.4
      }
    }
  ]
  name "solid(6)"
  boundingObject USE box
  physics Physics {
    mass 1
  }
}
Solid {
  translation 3.2295000011778208 -8.47761 0.1995900363687174
  rotation 1.6504505249922225e-08 0.9999807563479387 0.006203783829569306 5.317715073188243e-06
  children [
    DEF box Shape {
      appearance PBRAppearance {
        baseColor 1 0 0
        metalness 0
      }
      geometry Box {
        size 0.4 0.4 0.4
      }
    }
  ]
  name "solid(7)"
  boundingObject USE box
  physics Physics {
    mass 1
  }
}
Solid {
  translation -3.6713379678283755 -8.477609999506255 0.19962616132227048
  rotation -8.400112009395137e-09 0.9999999953667145 9.626302888371585e-05 0.0003302897401244874
  children [
    DEF box Shape {
      appearance PBRAppearance {
        baseColor 1 0 0
        metalness 0
      }
      geometry Box {
        size 0.4 0.4 0.4
      }
    }
  ]
  name "solid(8)"
  boundingObject USE box
  physics Physics {
    mass 1
  }
}
Solid {
  translation -4.071141694007973 -8.477610000493577 0.19962925977749038
  rotation 5.4028175428380455e-09 -0.9999999944945788 0.00010493256161040196 0.00032453998972263023
  children [
    DEF box Shape {
      appearance PBRAppearance {
        baseColor 1 0 0
        metalness 0
      }
      geometry Box {
        size 0.4 0.4 0.4
      }
    }
  ]
  name "solid(9)"
  boundingObject USE box
  physics Physics {
    mass 1
  }
}
Robot {
  translation 1.9802139167899722 2.729825921540703 0.079016228097968
  rotation 0.653501675932717 -0.33341806794527 0.6795350995502538 2.5855470794793054
  children [
    Solid {
      rotation 0.5773502691896258 0.5773502691896258 0.5773502691896258 0
      children [
        Hinge2Joint {
          jointParameters HingeJointParameters {
            position -0.303627679649805
            anchor 0 0.13 0
          }
          jointParameters2 JointParameters {
            position -0.10077671591386973
          }
          device [
            RotationalMotor {
              name "link1"
            }
          ]
          device2 [
            RotationalMotor {
              name "link12"
            }
          ]
          endPoint Solid {
            translation 7.22276960237519e-05 0.13070040101814637 -0.011798000196132877
            rotation -0.9482347387274781 -0.017557131067775355 -0.3170845745524374 0.32005002504037283
            children [
              DEF Encoders Hinge2Joint {
                jointParameters HingeJointParameters {
                }
                jointParameters2 JointParameters {
                }
                device [
                  PositionSensor {
                    name "link1Encoder"
                  }
                ]
                device2 [
                  PositionSensor {
                    name "link12Encoder"
                  }
                ]
              }
              Solid {
                translation -1.87158e-08 0.09 0.01
                rotation 3.390508950807168e-09 0.70710578118615 0.707107781185531 3.14159
                children [
                  DistanceSensor {
                    translation -0.0711263 0.00746587 -0.0137034
                    rotation 0.5849341057359155 0.7907431429390924 -0.18049203262673547 2.46011
                    children [
                      DEF ds Shape {
                        appearance PBRAppearance {
                          metalness 0
                        }
                        geometry Box {
                          size 0.02 0.02 0.02
                        }
                      }
                    ]
                    name "frontRightDs"
                    boundingObject USE ds
                    physics Physics {
                    }
                    lookupTable [
                      0 0 0
                      1 1000 0
                    ]
                  }
                  DistanceSensor {
                    translation -0.0662512 -0.0190048 -0.0112132
                    rotation 0.6116340798996 -0.45680305967355794 -0.6459370843807046 2.54594
                    children [
                      DEF ds Shape {
                        appearance PBRAppearance {
                          metalness 0
                        }
                        geometry Box {
                          size 0.02 0.02 0.02
                        }
                      }
                    ]
                    name "frontLeftDs"
                    boundingObject USE ds
                    physics Physics {
                    }
                    lookupTable [
                      0 0 0
                      1 1000 0
                    ]
                  }
                  TouchSensor {
                    translation -0.0018883677561602752 0.002186576613008473 0.006362356350624765
                    rotation 2.320102890540875e-05 -5.102495983194514e-05 0.9999999984290828 -0.5235985348596808
                    children [
                      DEF segment Shape {
                        geometry Cylinder {
                          height 0.1
                          radius 0.075
                        }
                      }
                    ]
                    name "segment1TouchSensor"
                    boundingObject USE segment
                    physics Physics {
                    }
                  }
                  Hinge2Joint {
                    jointParameters HingeJointParameters {
                      position -0.21501354940476422
                      anchor 0 0 0.08
                    }
                    jointParameters2 JointParameters {
                      position -0.10573715663842644
                    }
                    device [
                      RotationalMotor {
                        name "link2"
                      }
                    ]
                    device2 [
                      RotationalMotor {
                        name "link22"
                      }
                    ]
                    endPoint Solid {
                      translation 9.682895628974015e-05 0.001845838463314888 0.08576638120309438
                      rotation -0.8932497421878599 0.015473996688248176 -0.4492943951440012 0.23803022466449503
                      children [
                        DEF encoders Hinge2Joint {
                          jointParameters HingeJointParameters {
                          }
                          jointParameters2 JointParameters {
                          }
                          device [
                            PositionSensor {
                              name "link2Encoder"
                            }
                          ]
                          device2 [
                            PositionSensor {
                              name "link22Encoder"
                            }
                          ]
                        }
                        Solid {
                          translation 0 0 0.09
                          children [
                            Solid {
                              translation -0.14 0 5.14248e-07
                              rotation 0 1 0 1.5708
                              children [
                                Camera {
                                  translation 0 5.30718e-08 -0.1
                                  rotation 4.7949e-09 -1 1.32679e-06 3.14159
                                  name "rearCamera"
                                  recognitionColors [
                                    1 0 0
                                  ]
                                  fieldOfView 0.78
                                  width 128
                                  height 128
                                  antiAliasing TRUE
                                  recognition Recognition {
                                    frameColor 0 1 0
                                  }
                                }
                                Camera {
                                  translation 0 5.30718e-08 -0.1
                                  rotation -0.7071067811862364 -0.7071067811862364 9.381857096790023e-07 3.14159
                                  name "rightCamera"
                                  recognitionColors [
                                    1 0 0
                                  ]
                                  fieldOfView 0.78
                                  width 128
                                  height 128
                                  antiAliasing TRUE
                                  recognition Recognition {
                                  }
                                }
                                Camera {
                                  translation 0 5.30718e-08 -0.1
                                  rotation 0.7071067811862364 -0.7071067811862364 9.381857096790023e-07 3.14159
                                  name "leftCamera"
                                  recognitionColors [
                                    0 0 0
                                  ]
                                  fieldOfView 0.78
                                  width 128
                                  height 128
                                  antiAliasing TRUE
                                  recognition Recognition {
                                    frameThickness 3
                                  }
                                }
                                Camera {
                                  translation 0 5.30718e-08 -0.1
                                  rotation 1 0 0 3.14159
                                  name "frontCamera"
                                  recognitionColors [
                                    0 0 0
                                  ]
                                  fieldOfView 0.78
                                  width 128
                                  height 128
                                  antiAliasing TRUE
                                  recognition Recognition {
                                  }
                                }
                                DEF pole Shape {
                                  appearance PBRAppearance {
                                    baseColor 1 0 0
                                    metalness 0
                                  }
                                  geometry Capsule {
                                    height 0.2
                                    radius 0.01
                                  }
                                }
                              ]
                              name "solid(1)"
                              boundingObject USE pole
                              physics Physics {
                              }
                            }
                            TouchSensor {
                              translation 0.0009215761730072963 0.0007875352503723398 0.0031447118390723894
                              rotation -0.7737954430604949 0.3335773761237423 -0.5384856046703681 -4.7290547525946636e-05
                              name "segment2TouchSensor"
                              boundingObject USE segment
                              physics Physics {
                              }
                            }
                            RangeFinder {
                              translation -0.058508 -0.0234795 0
                              rotation 0 0 1 -2.3561953071795863
                              children [
                                DEF rangeFinder Shape {
                                  appearance PBRAppearance {
                                    baseColor 0 0.6 0
                                  }
                                  geometry Box {
                                    size 0.05 0.05 0.05
                                  }
                                }
                              ]
                              name "leftRangeFinder"
                              boundingObject USE rangeFinder
                              physics Physics {
                              }
                            }
                            RangeFinder {
                              translation -0.0565345 0.0250965 0
                              rotation 0 0 1 2.3562
                              children [
                                DEF rangeFinder Shape {
                                  appearance PBRAppearance {
                                    baseColor 0 0.6 0
                                  }
                                  geometry Box {
                                    size 0.05 0.05 0.05
                                  }
                                }
                              ]
                              name "rightRangeFinder"
                              boundingObject USE rangeFinder
                              physics Physics {
                              }
                            }
                            Hinge2Joint {
                              jointParameters HingeJointParameters {
                                position -0.08828278582821533
                                anchor 0 0 0.08
                              }
                              jointParameters2 JointParameters {
                                position -0.10575194519871728
                              }
                              device [
                                RotationalMotor {
                                  name "link3"
                                }
                              ]
                              device2 [
                                RotationalMotor {
                                  name "link32"
                                }
                              ]
                              endPoint Solid {
                                translation -0.0008164656971405268 0.0014419955381329034 0.08880421391370048
                                rotation -0.6449873459219558 -0.16273128265685238 -0.7466658243454075 0.1404663067832962
                                children [
                                  DEF encoders Hinge2Joint {
                                    jointParameters HingeJointParameters {
                                    }
                                    jointParameters2 JointParameters {
                                    }
                                    device [
                                      PositionSensor {
                                        name "link3Encoder"
                                      }
                                    ]
                                    device2 [
                                      PositionSensor {
                                        name "link32Encoder"
                                      }
                                    ]
                                  }
                                  Solid {
                                    translation 0 0 0.09
                                    children [
                                      DistanceSensor {
                                        translation -0.0669149 -0.0209822 0.0256218
                                        rotation 0.34520401974964043 -0.7647550437527846 -0.5440440311255761 2.22833
                                        children [
                                          DEF ds Shape {
                                            appearance PBRAppearance {
                                              metalness 0
                                            }
                                            geometry Box {
                                              size 0.02 0.02 0.02
                                            }
                                          }
                                        ]
                                        name "backLeftDs"
                                        boundingObject USE ds
                                        physics Physics {
                                        }
                                        lookupTable [
                                          0 0 0
                                          1 1000 0
                                        ]
                                      }
                                      DistanceSensor {
                                        translation -0.0708338 0.00845135 0.025653
                                        rotation -0.5030969446801573 0.05168819431643779 -0.8626829051405834 -2.5232353071795863
                                        children [
                                          DEF ds Shape {
                                            appearance PBRAppearance {
                                              metalness 0
                                            }
                                            geometry Box {
                                              size 0.02 0.02 0.02
                                            }
                                          }
                                        ]
                                        name "backRightDs"
                                        boundingObject USE ds
                                        physics Physics {
                                        }
                                        lookupTable [
                                          0 0 0
                                          1 1000 0
                                        ]
                                      }
                                      TouchSensor {
                                        translation -0.0015220403263549037 -0.0006156496214739793 0.005844291071864127
                                        rotation -0.973900232960361 -0.19001888084217178 -0.12414169792315242 -0.0011996967398122393
                                        name "segment3TouchSensor"
                                        boundingObject USE segment
                                        physics Physics {
                                        }
                                      }
                                      Hinge2Joint {
                                        jointParameters HingeJointParameters {
                                          position -0.3223315907993867
                                          anchor 0 0 0.08
                                        }
                                        jointParameters2 JointParameters {
                                          position -0.10703975134443683
                                        }
                                        device [
                                          RotationalMotor {
                                            name "link4"
                                          }
                                        ]
                                        device2 [
                                          RotationalMotor {
                                            name "link42"
                                          }
                                        ]
                                        endPoint Solid {
                                          translation -0.00023790909815051215 0.0010807334322108712 0.08307737451269816
                                          rotation -0.9486128790634919 -0.054635793742680114 -0.3116865985521034 0.33975965811193926
                                          children [
                                            DEF encoders Hinge2Joint {
                                              jointParameters HingeJointParameters {
                                              }
                                              jointParameters2 JointParameters {
                                              }
                                              device [
                                                PositionSensor {
                                                  name "link4Encoder"
                                                }
                                              ]
                                              device2 [
                                                PositionSensor {
                                                  name "link42Encoder"
                                                }
                                              ]
                                            }
                                            Solid {
                                              translation 0 0 0.08
                                              children [
                                                RangeFinder {
                                                  translation -0.0775204 0.0214102 0.0141602
                                                  rotation -0.4029860852434542 -0.6598321395739773 -0.6342111341543784 2.32616
                                                  children [
                                                    DEF rangeFinder Shape {
                                                      appearance PBRAppearance {
                                                        baseColor 0 0.6 0
                                                      }
                                                      geometry Box {
                                                        size 0.05 0.05 0.05
                                                      }
                                                    }
                                                  ]
                                                  name "backRangeFinder"
                                                  boundingObject USE rangeFinder
                                                  physics Physics {
                                                  }
                                                }
                                                TouchSensor {
                                                  translation 0.008319615524668603 0.003085558248521303 -0.020105856493219054
                                                  rotation -0.28809246762689644 0.24340903156684904 0.9261505133877185 -6.062389022076786e-05
                                                  name "segment4TouchSensor"
                                                  boundingObject USE segment
                                                  physics Physics {
                                                  }
                                                }
                                                Solid {
                                                  translation 0 0 0.05
                                                  children [
                                                    DEF tail Shape {
                                                      appearance PBRAppearance {
                                                        baseColor 0 0 0
                                                        metalness 0
                                                      }
                                                      geometry Sphere {
                                                        radius 0.075
                                                      }
                                                    }
                                                  ]
                                                  boundingObject USE tail
                                                  physics Physics {
                                                  }
                                                }
                                                DEF segment Shape {
                                                  appearance PBRAppearance {
                                                    baseColor 0 1 0
                                                    metalness 0
                                                  }
                                                  geometry Cylinder {
                                                    height 0.1
                                                    radius 0.075
                                                  }
                                                }
                                              ]
                                              boundingObject USE segment
                                              physics Physics {
                                              }
                                            }
                                            DEF joint Shape {
                                              appearance PBRAppearance {
                                                baseColor 0 1 0
                                                metalness 0
                                              }
                                              geometry Sphere {
                                                radius 0.05
                                              }
                                            }
                                          ]
                                          boundingObject USE joint
                                          physics Physics {
                                          }
                                        }
                                      }
                                      DEF segment Shape {
                                        appearance PBRAppearance {
                                          baseColor 0 1 0
                                          metalness 0
                                        }
                                        geometry Cylinder {
                                          height 0.1
                                          radius 0.075
                                        }
                                      }
                                    ]
                                    boundingObject USE segment
                                    physics Physics {
                                    }
                                  }
                                  DEF joint Shape {
                                    appearance PBRAppearance {
                                      baseColor 0 1 0
                                      metalness 0
                                    }
                                    geometry Sphere {
                                      radius 0.05
                                    }
                                  }
                                ]
                                boundingObject USE joint
                                physics Physics {
                                }
                              }
                            }
                            DEF segment Shape {
                              appearance PBRAppearance {
                                baseColor 0 1 0
                                metalness 0
                              }
                              geometry Cylinder {
                                height 0.1
                                radius 0.075
                              }
                            }
                          ]
                          boundingObject USE segment
                          physics Physics {
                          }
                        }
                        DEF link Shape {
                          appearance PBRAppearance {
                            baseColor 0 1 0
                            metalness 0
                          }
                          geometry Sphere {
                            radius 0.05
                          }
                        }
                      ]
                      boundingObject USE link
                      physics Physics {
                      }
                    }
                  }
                  DEF segment Shape {
                    appearance PBRAppearance {
                      baseColor 0 1 0
                      metalness 0
                    }
                    geometry Cylinder {
                      height 0.1
                      radius 0.075
                    }
                  }
                ]
                boundingObject USE segment
                physics Physics {
                }
              }
              DEF joint Shape {
                appearance PBRAppearance {
                  baseColor 0 1 0
                  metalness 0
                }
                geometry Sphere {
                  radius 0.05
                }
              }
            ]
            name "solid(1)"
            boundingObject USE joint
            physics Physics {
            }
          }
        }
        DEF neck Solid {
          translation 0 0.05 9.99998e-08
          rotation -1 0 0 1.5708
          children [
            TouchSensor {
              translation 7.825504924252602e-05 -0.007777688996175591 0.0002835181133158393
              rotation 0.6371569829558098 -0.3832398919274909 0.6686988592079807 0.20199933521303573
              name "neckTouchSensor"
              boundingObject USE segment
              physics Physics {
              }
            }
            Compass {
            }
            InertialUnit {
              name "imu"
              boundingObject USE segment
            }
            GPS {
            }
            RangeFinder {
              translation 0.0486092 0.0130347 -0.0844306
              rotation 0.8429630744256347 0.2626550231899444 -0.4694950414519538 2.23099
              children [
                DEF rangeFinder Shape {
                  appearance PBRAppearance {
                    baseColor 0 0.6 0
                  }
                  geometry Box {
                    size 0.05 0.05 0.05
                  }
                }
              ]
              name "rangeFinder"
              boundingObject USE rangeFinder
              physics Physics {
              }
            }
            DEF neck Shape {
              appearance PBRAppearance {
                baseColor 0 0.8 0
                metalness 0
              }
              geometry Cylinder {
                height 0.1
                radius 0.075
              }
            }
          ]
          name "neck"
          boundingObject USE neck
          physics Physics {
          }
        }
        DEF head Shape {
          appearance PBRAppearance {
            baseColor 0 0.6 0
            metalness 0
          }
          geometry Sphere {
            radius 0.075
          }
        }
      ]
      name "snakeBot"
      boundingObject USE head
      physics Physics {
      }
    }
  ]
  name "SnakeBot"
  boundingObject USE head
  physics Physics {
  }
  controller "first_controller"
}
