#VRML_SIM R2023b utf8

EXTERNPROTO "https://raw.githubusercontent.com/cyberbotics/webots/R2023b/projects/objects/backgrounds/protos/TexturedBackground.proto"
EXTERNPROTO "https://raw.githubusercontent.com/cyberbotics/webots/R2023b/projects/objects/backgrounds/protos/TexturedBackgroundLight.proto"
EXTERNPROTO "https://raw.githubusercontent.com/cyberbotics/webots/R2023b/projects/objects/floors/protos/RectangleArena.proto"

WorldInfo {
}
Viewpoint {
  orientation -0.43794614127225384 -0.33563471063851164 0.8339979126828471 4.464280688605299
  position -7.78673547912703 8.942291253320985 3.132940020299772
}
TexturedBackground {
}
TexturedBackgroundLight {
}
RectangleArena {
  translation -0.7 -2.08 3.28841e-06
  rotation 0 -1 0 -5.307179586466759e-06
  floorSize 20 20
  floorTileSize 1 1
  wallHeight 0.6
}
DEF maze Solid {
  translation -7.89 -0.09 0.2
  children [
    DEF wall Solid {
      translation -1.7300616418090167 7.267590133742707 -0.018368679589836512
      rotation -0.018213643618166037 0.9789548136641409 -0.20326272651412872 1.0473350289855915e-05
      children [
        DEF wall Shape {
          appearance PBRAppearance {
            baseColor 0 0 0
          }
          geometry Box {
            size 0.1 1.5 0.4
          }
        }
      ]
      boundingObject USE wall
      physics Physics {
      }
    }
    DEF wall Solid {
      translation -0.09293077018235518 7.274839680986259 -0.018342131962349323
      rotation 0.00021952563701279278 0.0001919151046613448 -0.9999999574885429 0.0022463508327087646
      children [
        DEF wall Shape {
          appearance PBRAppearance {
            baseColor 0 0 0
          }
          geometry Box {
            size 0.1 1.5 0.4
          }
        }
      ]
      name "solid(1)"
      boundingObject USE wall
      physics Physics {
      }
    }
    DEF wall Solid {
      translation -0.1181016297233155 5.776424859290918 -0.01834216825454968
      rotation -1.8777137603535103e-05 -1.788075831566653e-05 -0.9999999996638488 0.023546574708520784
      children [
        DEF wall Shape {
          appearance PBRAppearance {
            baseColor 0 0 0
          }
          geometry Box {
            size 0.1 1.5 0.4
          }
        }
      ]
      name "solid(2)"
      boundingObject USE wall
      physics Physics {
      }
    }
    DEF wall Solid {
      translation -1.7300114034240854 5.774412994153312 -0.01834278445899226
      rotation -0.41675479848623065 -0.03999879961290156 0.9081384993315879 5.709080815227575e-06
      children [
        DEF wall Shape {
          appearance PBRAppearance {
            baseColor 0 0 0
          }
          geometry Box {
            size 0.1 1.5 0.4
          }
        }
      ]
      name "solid(3)"
      boundingObject USE wall
      physics Physics {
      }
    }
    DEF wall Solid {
      translation -1.7300030963452846 4.278352595435694 -0.018338978971734782
      rotation 0.02983532264378896 -0.002463474900415659 0.9995517919618553 1.0982970044197342e-05
      children [
        DEF wall Shape {
          appearance PBRAppearance {
            baseColor 0 0 0
          }
          geometry Box {
            size 0.1 1.5 0.4
          }
        }
      ]
      name "solid(4)"
      boundingObject USE wall
      physics Physics {
      }
    }
    DEF wall Solid {
      translation -0.9399966771368975 3.4796310089936537 -0.018339219478724994
      rotation -1.608128147300994e-09 8.535538397237464e-09 -1 1.5705195910642418
      children [
        DEF wall Shape {
          appearance PBRAppearance {
            baseColor 0 0 0
          }
          geometry Box {
            size 0.1 1.5 0.4
          }
        }
      ]
      name "solid(5)"
      boundingObject USE wall
      physics Physics {
      }
    }
    DEF wall Solid {
      translation 0.5600020022904335 3.479999210351084 -0.018339175005873454
      rotation -1.052131711308002e-08 9.866877557790865e-09 -0.9999999999999999 1.5707946173509841
      children [
        DEF wall Shape {
          appearance PBRAppearance {
            baseColor 0 0 0
          }
          geometry Box {
            size 0.1 1.5 0.4
          }
        }
      ]
      name "solid(7)"
      boundingObject USE wall
      physics Physics {
      }
    }
    DEF wall Solid {
      translation 0.6454522054765652 5.088872011023981 -0.01834203421525238
      rotation 6.018924101355955e-09 4.758254105854105e-08 -0.9999999999999989 1.5697552257346
      children [
        DEF wall Shape {
          appearance PBRAppearance {
            baseColor 0 0 0
          }
          geometry Box {
            size 0.1 1.5 0.4
          }
        }
      ]
      name "solid(6)"
      boundingObject USE wall
      physics Physics {
      }
    }
    DEF wall Solid {
      translation 2.1254598243784564 5.090000762703707 -0.018342086661207818
      rotation 5.484410708468827e-09 4.624706299286133e-09 -1 1.5708905082297213
      children [
        DEF wall Shape {
          appearance PBRAppearance {
            baseColor 0 0 0
          }
          geometry Box {
            size 0.1 1.5 0.4
          }
        }
      ]
      name "solid(8)"
      boundingObject USE wall
      physics Physics {
      }
    }
    DEF wall Solid {
      translation 2.910078667921213 4.329943266825733 -0.018342087783510153
      rotation -1.0487248118609798e-08 -1.3557222890925518e-08 -0.9999999999999999 0.007408337496841742
      children [
        DEF wall Shape {
          appearance PBRAppearance {
            baseColor 0 0 0
          }
          geometry Box {
            size 0.1 1.5 0.4
          }
        }
      ]
      name "solid(9)"
      boundingObject USE wall
      physics Physics {
      }
    }
    DEF wall Solid {
      translation 2.9000380289491163 2.829937300878982 -0.01834208767777315
      rotation 2.5103169284095226e-06 -3.0641117573597744e-09 -0.999999999996849 3.569682596782401e-05
      children [
        DEF wall Shape {
          appearance PBRAppearance {
            baseColor 0 0 0
          }
          geometry Box {
            size 0.1 1.5 0.4
          }
        }
      ]
      name "solid(10)"
      boundingObject USE wall
      physics Physics {
      }
    }
    DEF wall Solid {
      translation 2.113264698133679 0.5300088637575826 -0.018340714798318974
      rotation -1.0249355791278982e-08 9.446160740819994e-09 -0.9999999999999999 1.5708232515729124
      children [
        DEF wall Shape {
          appearance PBRAppearance {
            baseColor 0 0 0
          }
          geometry Box {
            size 0.1 1.5 0.4
          }
        }
      ]
      name "solid(12)"
      boundingObject USE wall
      physics Physics {
      }
    }
    DEF wall Solid {
      translation 0.6155763419130009 0.5300058196042684 -0.018340689653588566
      rotation -3.235927082823376e-10 3.352841886481724e-10 -1 1.5707824356219962
      children [
        DEF wall Shape {
          appearance PBRAppearance {
            baseColor 0 0 0
          }
          geometry Box {
            size 0.1 1.5 0.4
          }
        }
      ]
      name "solid(15)"
      boundingObject USE wall
      physics Physics {
      }
    }
    DEF wall Solid {
      translation -0.9373304119464949 -0.9873634663963694 -0.018340934190742675
      rotation -2.1907593293554874e-09 2.1191540765746584e-09 -1 1.5703764787754269
      children [
        DEF wall Shape {
          appearance PBRAppearance {
            baseColor 0 0 0
          }
          geometry Box {
            size 0.1 1.5 0.4
          }
        }
      ]
      name "solid(19)"
      boundingObject USE wall
      physics Physics {
      }
    }
    DEF wall Solid {
      translation 0.5862240827307588 -0.9624537185684291 -0.01834094217669871
      rotation -2.0145659498300553e-09 1.8070741445919303e-09 -0.9999999999999999 1.5833468219228128
      children [
        DEF wall Shape {
          appearance PBRAppearance {
            baseColor 0 0 0
          }
          geometry Box {
            size 0.1 1.5 0.4
          }
        }
      ]
      name "solid(20)"
      boundingObject USE wall
      physics Physics {
      }
    }
    DEF wall Solid {
      translation -0.15617324337338 -1.7446240319163282 -0.01834093436826259
      rotation 3.428502030899614e-10 1.955678982703003e-09 1 3.1311990824595455
      children [
        DEF wall Shape {
          appearance PBRAppearance {
            baseColor 0 0 0
          }
          geometry Box {
            size 0.1 1.5 0.4
          }
        }
      ]
      name "solid(24)"
      boundingObject USE wall
      physics Physics {
      }
    }
    DEF wall Solid {
      translation 2.1099995758042054 -2.480000201744659 -0.018340689069256372
      rotation -7.224716262542709e-12 -4.9584214588588806e-11 1 1.5707951656956505
      children [
        DEF wall Shape {
          appearance PBRAppearance {
            baseColor 0 0 0
          }
          geometry Box {
            size 0.1 1.5 0.4
          }
        }
      ]
      name "solid(21)"
      boundingObject USE wall
      physics Physics {
      }
    }
    DEF wall Solid {
      translation 2.9100046371583446 -1.7300083213415092 -0.01834068825755475
      rotation 9.018196864877919e-12 -2.9990351722306843e-10 1 3.1415867127249406
      children [
        DEF wall Shape {
          appearance PBRAppearance {
            baseColor 0 0 0
          }
          geometry Box {
            size 0.1 1.5 0.4
          }
        }
      ]
      name "solid(22)"
      boundingObject USE wall
      physics Physics {
      }
    }
    DEF wall Solid {
      translation 2.91115426664528 -0.2300075777653405 -0.01834068128340488
      rotation 3.2741051584206824e-10 -3.4373813000657025e-09 1 3.140742347500028
      children [
        DEF wall Shape {
          appearance PBRAppearance {
            baseColor 0 0 0
          }
          geometry Box {
            size 0.1 1.5 0.4
          }
        }
      ]
      name "solid(23)"
      boundingObject USE wall
      physics Physics {
      }
    }
    DEF wall Solid {
      translation 0.5701231899010448 2.0700983717476826 -0.018340918748637247
      rotation 9.69444223160442e-12 -4.063027187394748e-12 -0.9999999999999999 1.5709073878816222
      children [
        DEF wall Shape {
          appearance PBRAppearance {
            baseColor 0 0 0
          }
          geometry Box {
            size 0.1 1.5 0.4
          }
        }
      ]
      name "solid(14)"
      boundingObject USE wall
      physics Physics {
      }
    }
    DEF wall Solid {
      translation -0.9230273539794824 2.071099935447378 -0.018340918825832053
      rotation 7.155085013327077e-11 -8.530674862879661e-12 -1 1.5714496149295125
      children [
        DEF wall Shape {
          appearance PBRAppearance {
            baseColor 0 0 0
          }
          geometry Box {
            size 0.1 1.5 0.4
          }
        }
      ]
      name "solid(16)"
      boundingObject USE wall
      physics Physics {
      }
    }
    DEF wall Solid {
      translation -1.7107465563861508 1.30422970429929 -0.018340919463271488
      rotation 8.723068899319551e-08 4.969622265524263e-09 0.9999999999999961 0.008905927880052324
      children [
        DEF wall Shape {
          appearance PBRAppearance {
            baseColor 0 0 0
          }
          geometry Box {
            size 0.1 1.5 0.4
          }
        }
      ]
      name "solid(17)"
      boundingObject USE wall
      physics Physics {
      }
    }
    DEF wall Solid {
      translation -1.7034197102181485 -0.1910297238766944 -0.01834092434761453
      rotation 3.909992362105392e-06 4.4389152041024325e-07 -0.9999999999922575 0.0013435390552606098
      children [
        DEF wall Shape {
          appearance PBRAppearance {
            baseColor 0 0 0
          }
          geometry Box {
            size 0.1 1.5 0.4
          }
        }
      ]
      name "solid(18)"
      boundingObject USE wall
      physics Physics {
      }
    }
    DEF wall Solid {
      translation 2.900003253676929 1.3299827909382553 -0.018342068248557636
      rotation -0.01578106683649525 0.0009145161403751695 -0.9998750529889877 7.936609860177423e-07
      children [
        DEF wall Shape {
          appearance PBRAppearance {
            baseColor 0 0 0
          }
          geometry Box {
            size 0.1 1.5 0.4
          }
        }
      ]
      name "solid(13)"
      boundingObject USE wall
      physics Physics {
      }
    }
    DEF wall Solid {
      translation 1.3643499826360355 2.780043350071105 -0.01834091873669627
      rotation 3.748611647510466e-10 -1.6210071738092405e-10 1 0.003059430108059814
      children [
        DEF wall Shape {
          appearance PBRAppearance {
            baseColor 0 0 0
          }
          geometry Box {
            size 0.1 1.5 0.4
          }
        }
      ]
      name "solid(11)"
      boundingObject USE wall
      physics Physics {
      }
    }
  ]
  name "solid(1)"
}
Solid {
  translation 1.1021563375061314 -2.7976900002780263 0.19960132404549047
  rotation -6.212270125103544e-08 0.9997269375553803 -0.023367719746195212 5.3190651795671415e-06
  children [
    DEF box Shape {
      appearance PBRAppearance {
        baseColor 1 0 0
        metalness 0
      }
      geometry Box {
        size 0.4 0.4 0.4
      }
    }
  ]
  boundingObject USE box
  physics Physics {
    mass 1
  }
}
Solid {
  translation 0.10950300270092946 1.73239 0.19960659223500546
  rotation 1.6496087226552083e-08 0.9999807563477493 0.00620378386009307 5.3177150747539036e-06
  children [
    DEF box Shape {
      appearance PBRAppearance {
        baseColor 1 0 0
        metalness 0
      }
      geometry Box {
        size 0.4 0.4 0.4
      }
    }
  ]
  name "solid(2)"
  boundingObject USE box
  physics Physics {
    mass 1
  }
}
Solid {
  translation 6.398096533530441 -0.7076100000447352 0.19957321753979074
  rotation 1.6471720209942496e-08 0.9999807979886315 0.006197068179354111 5.317714853350669e-06
  children [
    DEF box Shape {
      appearance PBRAppearance {
        baseColor 1 0 0
        metalness 0
      }
      geometry Box {
        size 0.4 0.4 0.4
      }
    }
  ]
  name "solid(3)"
  boundingObject USE box
  physics Physics {
    mass 1
  }
}
Solid {
  translation 2.109500002702976 5.16239 0.19959597789175393
  rotation 1.6493682070965115e-08 0.9999807563476784 0.006203783871565353 5.317715074794789e-06
  children [
    DEF box Shape {
      appearance PBRAppearance {
        baseColor 1 0 0
        metalness 0
      }
      geometry Box {
        size 0.4 0.4 0.4
      }
    }
  ]
  name "solid(4)"
  boundingObject USE box
  physics Physics {
    mass 1
  }
}
Solid {
  translation 1.629502771289985 -0.7276100000000284 0.19959852532326205
  rotation 1.649238913558631e-08 0.9999807609496013 0.0062030420485582214 5.317715050495891e-06
  children [
    DEF box Shape {
      appearance PBRAppearance {
        baseColor 1 0 0
        metalness 0
      }
      geometry Box {
        size 0.4 0.4 0.4
      }
    }
  ]
  name "solid(5)"
  boundingObject USE box
  physics Physics {
    mass 1
  }
}
Solid {
  translation -0.9205199994672982 -4.45761 0.19961205875205618
  rotation 1.649047551091417e-08 0.9999807563483215 0.0062037837678848426 5.3177150747794475e-06
  children [
    DEF box Shape {
      appearance PBRAppearance {
        baseColor 1 0 0
        metalness 0
      }
      geometry Box {
        size 0.4 0.4 0.4
      }
    }
  ]
  name "solid(11)"
  boundingObject USE box
  physics Physics {
    mass 1
  }
}
Solid {
  translation 6.739480100710442 -4.45761 0.1995714057558918
  rotation 1.6496086527626443e-08 0.9999807563461248 0.006203784121969912 5.317715074791165e-06
  children [
    DEF box Shape {
      appearance PBRAppearance {
        baseColor 1 0 0
        metalness 0
      }
      geometry Box {
        size 0.4 0.4 0.4
      }
    }
  ]
  name "solid(12)"
  boundingObject USE box
  physics Physics {
    mass 1
  }
}
Solid {
  translation 5.799470049999132 -3.432344767363654 0.1995763945580441
  rotation 1.995406363689057e-07 0.9971799698697362 0.07504736964445859 5.332650979155126e-06
  children [
    DEF box Shape {
      appearance PBRAppearance {
        baseColor 1 0 0
        metalness 0
      }
      geometry Box {
        size 0.4 0.4 0.4
      }
    }
  ]
  name "solid(10)"
  boundingObject USE box
  physics Physics {
    mass 1
  }
}
Solid {
  translation 3.4295000478139173 1.8500032545549332 0.19958897241446033
  rotation -4.865492323988507e-08 0.999832550247656 -0.01829949357948939 5.318503324731455e-06
  children [
    DEF box Shape {
      appearance PBRAppearance {
        baseColor 1 0 0
        metalness 0
      }
      geometry Box {
        size 0.4 0.4 0.4
      }
    }
  ]
  name "solid(6)"
  boundingObject USE box
  physics Physics {
    mass 1
  }
}
Solid {
  translation 3.2295000025918217 -8.47761 0.1995900338506176
  rotation 1.6495285501769495e-08 0.9999807563477111 0.006203783866259838 5.3177150747754106e-06
  children [
    DEF box Shape {
      appearance PBRAppearance {
        baseColor 1 0 0
        metalness 0
      }
      geometry Box {
        size 0.4 0.4 0.4
      }
    }
  ]
  name "solid(7)"
  boundingObject USE box
  physics Physics {
    mass 1
  }
}
Solid {
  translation -3.6712818707441084 -8.477609999505477 0.1996263154606002
  rotation 8.057661752900645e-09 0.9999999748915511 0.000224091269511408 0.00014433608655651243
  children [
    DEF box Shape {
      appearance PBRAppearance {
        baseColor 1 0 0
        metalness 0
      }
      geometry Box {
        size 0.4 0.4 0.4
      }
    }
  ]
  name "solid(8)"
  boundingObject USE box
  physics Physics {
    mass 1
  }
}
Solid {
  translation -4.071197502383686 -8.477610000494515 0.19962911808114062
  rotation -9.352298475377858e-09 -0.9999999701600155 0.0002442948379855247 0.00013710642080053213
  children [
    DEF box Shape {
      appearance PBRAppearance {
        baseColor 1 0 0
        metalness 0
      }
      geometry Box {
        size 0.4 0.4 0.4
      }
    }
  ]
  name "solid(9)"
  boundingObject USE box
  physics Physics {
    mass 1
  }
}
Robot {
  translation -8.52778 6.11585 0.0765324
  rotation 0.5887138961435189 -0.5118099097103422 0.6256728896234911 2.10626
  children [
    Solid {
      rotation 0.5773502691896258 0.5773502691896258 0.5773502691896258 0
      children [
        Hinge2Joint {
          jointParameters HingeJointParameters {
            position -0.27761957363321127
            anchor 0 0.13 0
          }
          jointParameters2 JointParameters {
            position -0.09731326046467664
          }
          device [
            RotationalMotor {
              name "link1"
            }
          ]
          device2 [
            RotationalMotor {
              name "link12"
            }
          ]
          endPoint Solid {
            translation -0.00033173493275565644 0.1318770595490638 -0.011835665752613304
            rotation -0.9424815277732801 -0.0028734883594312196 -0.33424588684199574 0.29456468208065206
            children [
              DEF Encoders Hinge2Joint {
                jointParameters HingeJointParameters {
                }
                jointParameters2 JointParameters {
                }
                device [
                  PositionSensor {
                    name "link1Encoder"
                  }
                ]
                device2 [
                  PositionSensor {
                    name "link12Encoder"
                  }
                ]
              }
              Solid {
                translation -1.87158e-08 0.09 0.01
                rotation 3.390508950807168e-09 0.70710578118615 0.707107781185531 3.14159
                children [
                  DistanceSensor {
                    translation -0.071126 0.00746591 -0.0137034
                    rotation 0.5745980014348747 0.816664002039357 0.053824200134408716 3.0945
                    children [
                      DEF ds Shape {
                        appearance PBRAppearance {
                          metalness 0
                        }
                        geometry Box {
                          size 0.02 0.02 0.02
                        }
                      }
                    ]
                    name "frontRightDs"
                    boundingObject USE ds
                    physics Physics {
                    }
                    lookupTable [
                      0 0 0
                      1 1000 0
                    ]
                    numberOfRays 12
                    aperture 0.3
                  }
                  DistanceSensor {
                    translation -0.0662512 -0.0190048 -0.0112132
                    rotation 0.4884917695565045 -0.32440084696555854 -0.8100246178750268 2.17555
                    children [
                      DEF ds Shape {
                        appearance PBRAppearance {
                          metalness 0
                        }
                        geometry Box {
                          size 0.02 0.02 0.02
                        }
                      }
                    ]
                    name "frontLeftDs"
                    boundingObject USE ds
                    physics Physics {
                    }
                    lookupTable [
                      0 0 0
                      1 1000 0
                    ]
                    numberOfRays 12
                    aperture 0.3
                  }
                  TouchSensor {
                    translation -0.0016549254436041827 0.002832454609244195 0.007462538783280737
                    rotation -0.01491790956429287 -0.010807845590386117 -0.9998303088264157 0.5137350130876056
                    children [
                      DEF segment Shape {
                        geometry Cylinder {
                          height 0.1
                          radius 0.075
                        }
                      }
                    ]
                    name "segment1TouchSensor"
                    boundingObject USE segment
                    physics Physics {
                    }
                  }
                  Hinge2Joint {
                    jointParameters HingeJointParameters {
                      position -0.27694038078406
                      anchor 0 0 0.08
                    }
                    jointParameters2 JointParameters {
                      position -0.09719160520053227
                    }
                    device [
                      RotationalMotor {
                        name "link2"
                      }
                    ]
                    device2 [
                      RotationalMotor {
                        name "link22"
                      }
                    ]
                    endPoint Solid {
                      translation 9.192873978237538e-05 0.0021999415759684946 0.08564087349866645
                      rotation -0.9410913322905073 0.005354679796119126 -0.33811008812509435 0.29178133967120806
                      children [
                        DEF encoders Hinge2Joint {
                          jointParameters HingeJointParameters {
                          }
                          jointParameters2 JointParameters {
                          }
                          device [
                            PositionSensor {
                              name "link2Encoder"
                            }
                          ]
                          device2 [
                            PositionSensor {
                              name "link22Encoder"
                            }
                          ]
                        }
                        Solid {
                          translation 0 0 0.09
                          children [
                            Solid {
                              translation -0.14 0 5.14248e-07
                              rotation 0 1 0 1.5708
                              children [
                                Camera {
                                  translation 0 5.30718e-08 -0.1
                                  rotation 4.7949e-09 -1 1.32679e-06 3.14159
                                  name "rearCamera"
                                  recognitionColors [
                                    1 0 0
                                  ]
                                  fieldOfView 0.78
                                  width 128
                                  height 128
                                  antiAliasing TRUE
                                  recognition Recognition {
                                    frameColor 0 1 0
                                  }
                                }
                                Camera {
                                  translation 0 5.30718e-08 -0.1
                                  rotation -0.7071067811862364 -0.7071067811862364 9.381857096790023e-07 3.14159
                                  name "rightCamera"
                                  recognitionColors [
                                    1 0 0
                                  ]
                                  fieldOfView 0.78
                                  width 128
                                  height 128
                                  antiAliasing TRUE
                                  recognition Recognition {
                                  }
                                }
                                Camera {
                                  translation 0 5.30718e-08 -0.1
                                  rotation 0.7071067811862364 -0.7071067811862364 9.381857096790023e-07 3.14159
                                  name "leftCamera"
                                  recognitionColors [
                                    0 0 0
                                  ]
                                  fieldOfView 0.78
                                  width 128
                                  height 128
                                  antiAliasing TRUE
                                  recognition Recognition {
                                    frameThickness 3
                                  }
                                }
                                Camera {
                                  translation 0 5.30718e-08 -0.1
                                  rotation 1 0 0 3.14159
                                  name "frontCamera"
                                  recognitionColors [
                                    0 0 0
                                  ]
                                  fieldOfView 0.78
                                  width 128
                                  height 128
                                  antiAliasing TRUE
                                  recognition Recognition {
                                  }
                                }
                                DEF pole Shape {
                                  appearance PBRAppearance {
                                    baseColor 1 0 0
                                    metalness 0
                                  }
                                  geometry Capsule {
                                    height 0.2
                                    radius 0.01
                                  }
                                }
                              ]
                              name "solid(1)"
                              boundingObject USE pole
                              physics Physics {
                              }
                            }
                            TouchSensor {
                              translation 0.0006947375740955497 0.0005913146650318168 0.003323882268782885
                              rotation 0.30981650989833387 0.37561654744579853 0.8734563180144236 0.0009553581172230502
                              name "segment2TouchSensor"
                              boundingObject USE segment
                              physics Physics {
                              }
                            }
                            RangeFinder {
                              translation -0.058508 -0.0234795 0
                              rotation 0 0 1 -2.3561953071795863
                              children [
                                DEF rangeFinder Shape {
                                  appearance PBRAppearance {
                                    baseColor 0 0.6 0
                                  }
                                  geometry Box {
                                    size 0.05 0.05 0.05
                                  }
                                }
                              ]
                              name "leftRangeFinder"
                              boundingObject USE rangeFinder
                              physics Physics {
                              }
                            }
                            RangeFinder {
                              translation -0.0565345 0.0250965 0
                              rotation 0 0 1 2.3562
                              children [
                                DEF rangeFinder Shape {
                                  appearance PBRAppearance {
                                    baseColor 0 0.6 0
                                  }
                                  geometry Box {
                                    size 0.05 0.05 0.05
                                  }
                                }
                              ]
                              name "rightRangeFinder"
                              boundingObject USE rangeFinder
                              physics Physics {
                              }
                            }
                            Hinge2Joint {
                              jointParameters HingeJointParameters {
                                position -0.1745435231785182
                                anchor 0 0 0.08
                              }
                              jointParameters2 JointParameters {
                                position -0.09726335459259614
                              }
                              device [
                                RotationalMotor {
                                  name "link3"
                                }
                              ]
                              device2 [
                                RotationalMotor {
                                  name "link32"
                                }
                              ]
                              endPoint Solid {
                                translation -0.0008220397753819543 0.0021883017936600055 0.0886484528022274
                                rotation -0.8722603219599028 -0.1315531455580086 -0.4710156055038946 0.2026051586760534
                                children [
                                  DEF encoders Hinge2Joint {
                                    jointParameters HingeJointParameters {
                                    }
                                    jointParameters2 JointParameters {
                                    }
                                    device [
                                      PositionSensor {
                                        name "link3Encoder"
                                      }
                                    ]
                                    device2 [
                                      PositionSensor {
                                        name "link32Encoder"
                                      }
                                    ]
                                  }
                                  Solid {
                                    translation 0 0 0.09
                                    children [
                                      DistanceSensor {
                                        translation -0.0719313 -0.0078862 0.0237971
                                        rotation -0.42771792078365434 0.6899988722073908 0.5839168918545142 -2.3762053071795863
                                        children [
                                          DEF ds Shape {
                                            appearance PBRAppearance {
                                              metalness 0
                                            }
                                            geometry Box {
                                              size 0.02 0.02 0.02
                                            }
                                          }
                                        ]
                                        name "backLeftDs"
                                        boundingObject USE ds
                                        physics Physics {
                                        }
                                        lookupTable [
                                          0 0 0
                                          1 1000 0
                                        ]
                                        numberOfRays 12
                                        aperture 0.3
                                      }
                                      DistanceSensor {
                                        translation -0.0708338 0.00845135 0.025653
                                        rotation 0.7406046362064972 0.6710526703712216 -0.03454108303302333 -2.854285307179586
                                        children [
                                          DEF ds Shape {
                                            appearance PBRAppearance {
                                              metalness 0
                                            }
                                            geometry Box {
                                              size 0.02 0.02 0.02
                                            }
                                          }
                                        ]
                                        name "backRightDs"
                                        boundingObject USE ds
                                        physics Physics {
                                        }
                                        lookupTable [
                                          0 0 0
                                          1 1000 0
                                        ]
                                        numberOfRays 12
                                        aperture 0.3
                                      }
                                      TouchSensor {
                                        translation -0.0011458442662393153 -0.00025755174606878484 0.006035387033870521
                                        rotation 0.9731368018050591 0.19260760951363362 0.12612324817441278 0.0012017805766253963
                                        name "segment3TouchSensor"
                                        boundingObject USE segment
                                        physics Physics {
                                        }
                                      }
                                      Hinge2Joint {
                                        jointParameters HingeJointParameters {
                                          position 0.3460577666091756
                                          anchor 0 0 0.08
                                        }
                                        jointParameters2 JointParameters {
                                          position -0.09664949977373635
                                        }
                                        device [
                                          RotationalMotor {
                                            name "link4"
                                          }
                                        ]
                                        device2 [
                                          RotationalMotor {
                                            name "link42"
                                          }
                                        ]
                                        endPoint Solid {
                                          translation -0.00023841812423997603 -0.0010612647063480587 0.08308410333857008
                                          rotation 0.9626763407712606 0.04293981148513557 -0.2672273105595246 0.3589123047513611
                                          children [
                                            DEF encoders Hinge2Joint {
                                              jointParameters HingeJointParameters {
                                              }
                                              jointParameters2 JointParameters {
                                              }
                                              device [
                                                PositionSensor {
                                                  name "link4Encoder"
                                                }
                                              ]
                                              device2 [
                                                PositionSensor {
                                                  name "link42Encoder"
                                                }
                                              ]
                                            }
                                            Solid {
                                              translation 0 0 0.08
                                              children [
                                                RangeFinder {
                                                  translation -0.0775204 0.0214102 0.0141602
                                                  rotation -0.3033810254019426 -0.6841660572848843 -0.6632320555320907 2.4962
                                                  children [
                                                    DEF rangeFinder Shape {
                                                      appearance PBRAppearance {
                                                        baseColor 0 0.6 0
                                                      }
                                                      geometry Box {
                                                        size 0.05 0.05 0.05
                                                      }
                                                    }
                                                  ]
                                                  name "backRangeFinder"
                                                  boundingObject USE rangeFinder
                                                  physics Physics {
                                                  }
                                                }
                                                TouchSensor {
                                                  translation 0.008997802749568073 0.002418654102484652 -0.020213819253466547
                                                  rotation -0.001100354750744069 -0.7657723971631621 -0.6431107408233879 9.559341588023864e-05
                                                  name "segment4TouchSensor"
                                                  boundingObject USE segment
                                                  physics Physics {
                                                  }
                                                }
                                                Solid {
                                                  translation 0 0 0.05
                                                  children [
                                                    DEF tail Shape {
                                                      appearance PBRAppearance {
                                                        baseColor 0 0 0
                                                        metalness 0
                                                      }
                                                      geometry Sphere {
                                                        radius 0.075
                                                      }
                                                    }
                                                  ]
                                                  boundingObject USE tail
                                                  physics Physics {
                                                  }
                                                }
                                                DEF segment Shape {
                                                  appearance PBRAppearance {
                                                    baseColor 0 1 0
                                                    metalness 0
                                                  }
                                                  geometry Cylinder {
                                                    height 0.1
                                                    radius 0.075
                                                  }
                                                }
                                              ]
                                              boundingObject USE segment
                                              physics Physics {
                                              }
                                            }
                                            DEF joint Shape {
                                              appearance PBRAppearance {
                                                baseColor 0 1 0
                                                metalness 0
                                              }
                                              geometry Sphere {
                                                radius 0.05
                                              }
                                            }
                                          ]
                                          boundingObject USE joint
                                          physics Physics {
                                          }
                                        }
                                      }
                                      DEF segment Shape {
                                        appearance PBRAppearance {
                                          baseColor 0 1 0
                                          metalness 0
                                        }
                                        geometry Cylinder {
                                          height 0.1
                                          radius 0.075
                                        }
                                      }
                                    ]
                                    boundingObject USE segment
                                    physics Physics {
                                    }
                                  }
                                  DEF joint Shape {
                                    appearance PBRAppearance {
                                      baseColor 0 1 0
                                      metalness 0
                                    }
                                    geometry Sphere {
                                      radius 0.05
                                    }
                                  }
                                ]
                                boundingObject USE joint
                                physics Physics {
                                }
                              }
                            }
                            DEF segment Shape {
                              appearance PBRAppearance {
                                baseColor 0 1 0
                                metalness 0
                              }
                              geometry Cylinder {
                                height 0.1
                                radius 0.075
                              }
                            }
                          ]
                          boundingObject USE segment
                          physics Physics {
                          }
                        }
                        DEF link Shape {
                          appearance PBRAppearance {
                            baseColor 0 1 0
                            metalness 0
                          }
                          geometry Sphere {
                            radius 0.05
                          }
                        }
                      ]
                      boundingObject USE link
                      physics Physics {
                      }
                    }
                  }
                  DEF segment Shape {
                    appearance PBRAppearance {
                      baseColor 0 1 0
                      metalness 0
                    }
                    geometry Cylinder {
                      height 0.1
                      radius 0.075
                    }
                  }
                ]
                boundingObject USE segment
                physics Physics {
                }
              }
              DEF joint Shape {
                appearance PBRAppearance {
                  baseColor 0 1 0
                  metalness 0
                }
                geometry Sphere {
                  radius 0.05
                }
              }
            ]
            name "solid(1)"
            boundingObject USE joint
            physics Physics {
            }
          }
        }
        DEF neck Solid {
          translation 0 0.05 9.99998e-08
          rotation -1 0 0 1.5708
          children [
            TouchSensor {
              translation -0.0014766905275077624 -0.008272302219561212 0.0007364832153433643
              rotation 0.6128493823272386 -0.43757230057716867 0.657986410459005 0.21093145107483688
              name "neckTouchSensor"
              boundingObject USE segment
              physics Physics {
              }
            }
            Compass {
            }
            InertialUnit {
              name "imu"
              boundingObject USE segment
              physics Physics {
              }
            }
            GPS {
            }
            RangeFinder {
              translation 0.0486092 0.0130347 -0.0844306
              rotation 0.8429630744256347 0.2626550231899444 -0.4694950414519538 2.23099
              children [
                DEF rangeFinder Shape {
                  appearance PBRAppearance {
                    baseColor 0 0.6 0
                  }
                  geometry Box {
                    size 0.05 0.05 0.05
                  }
                }
              ]
              name "rangeFinder"
              boundingObject USE rangeFinder
              physics Physics {
              }
            }
            DEF neck Shape {
              appearance PBRAppearance {
                baseColor 0 0.8 0
                metalness 0
              }
              geometry Cylinder {
                height 0.1
                radius 0.075
              }
            }
          ]
          name "neck"
          boundingObject USE neck
          physics Physics {
          }
        }
        DEF head Shape {
          appearance PBRAppearance {
            baseColor 0 0.6 0
            metalness 0
          }
          geometry Sphere {
            radius 0.075
          }
        }
      ]
      name "snakeBot"
      boundingObject USE head
      physics Physics {
      }
    }
  ]
  name "SnakeBot"
  boundingObject USE head
  physics Physics {
  }
  controller "first_controller"
}
